Workbook

Sheet cross checks all
A1: Type of change | B1: Status | C1: Category | D1: Sense Check | E1: X-Check No. | F1: Inscope | G1: Reference X-Check (Condition) | H1: Applicable Quarters | I1: Included RUs | J1: Excluded RUs | K1: Reference X-Check (Limit, %) | L1: Description | M1: Version Spanning Validation | N1: Absolute (result) | O1: Account No. | P1: Account description | Q1: Exclude Account Type | R1: SubA No. | S1: SubA Description | T1: SST account category | U1: SII account category | V1: Operator (X-Check Term) | W1: Ending Balance Prior Year | X1: Operator 1 | Y1: Limit 1 | Z1: Operator 2 | AA1: Limit 2 | AB1: Absolute (Account/SubA) | AC1: % | AD1: Grouping By | AE1: Deactivation due to Hyperinflation (FIP) | AF1: Exclude Z-Core | AG1: IFRS New RFD | AH1: IFRS New SFD | AI1: IFRS New CFD | AJ1: Actual IFRS RFD | AK1: Actual IFRS SFD | AL1: Actual IFRS CFD | AM1: MHC RFD | AN1: MHC SFD | AO1: MHC CFD | AP1: Curr. Simulation Versions RFD | AQ1: Curr. Simulation Versions SFD | AR1: Curr. Simulation Versions CFD | AS1: Stammhaus SLST RFD | AT1: Stammhaus SLST SFD | AU1: Stammhaus SLST CFD | AV1: Stammhaus IFRS RFD | AW1: Stammhaus IFRS SFD | AX1: Stammhaus IFRS CFD | AY1: Plan/ Forecast (SU) RFD | AZ1: Plan/ Forecast (SU) SFD | BA1: Plan/ Forecast (SU) CFD | BB1: RI Assets RFD | BC1: RI Assets SFD | BD1: RI Assets CFD | BE1: Tax RFD | BF1: Tax SFD | BG1: Tax CFD | BH1: Equity RFD | BI1: Equity SFD | BJ1: Equity CFD | BK1: I/C RFD | BL1: I/C SFD | BM1: I/C CFD | BN1: IE GAAP RFD | BO1: IE GAAP SFD | BP1: IE GAAP CFD | BQ1: SST RFD | BR1: SST SFD | BS1: SST CFD | BT1: ZIC & ZLIC FINMA information RFD | BU1: ZIC & ZLIC FINMA information SFD | BV1: ZIC & ZLIC FINMA information CFD | BW1: SII RFD | BX1: SII SFD | BY1: SII CFD | BZ1: ZIP IFRS RFD | CA1: ZIP IFRS SFD | CB1: ZIP IFRS CFD | CC1: RI Assets IFRSN RFD | CD1: RI Assets IFRSN SFD | CE1: RI Assets IFRSN CFD | CF1: Equity IFRSN RFD | CG1: Equity IFRSN SFD | CH1: Equity IFRSN CFD | CI1: I/C IFRSN RFD | CJ1: I/C IFRSN SFD | CK1: I/C IFRSN CFD | CL1: Tax IFRSN RFD | CM1: Tax IFRSN SFD | CN1: Tax IFRSN CFD | CO1: DE GAAP RFD | CP1: DE GAAP SFD | CQ1: DE GAAP CFD
A2: Changed | B2: ACTIVE | C2: Loss allowance | E2: A011_09 | F2: =VLOOKUP(E2,Sheet2!$A:$A,1,FALSE) -> A011_09 | L2: A011_09 Transfer to 12-month ECL ToM should be total 0 | O2: 10891 | P2: Loss allow.stage1 -Am.Cost CDO/CLO | R2: 602 | S2: Transfer to 12-month ECL(S1) | V2: + | X2: >= | Y2: -5 | Z2: <= | AA2: 5 | AG2: e | AH2: e
A3: Changed | B3: ACTIVE | C3: Loss allowance | E3: A011_09 | F3: =VLOOKUP(E3,Sheet2!$A:$A,1,FALSE) -> A011_09 | L3: A011_09 Transfer to 12-month ECL ToM should be total 0 | O3: 10931 | P3: Loss allow.stage2 -Am.Cost CDO/CLO | R3: 602 | S3: Transfer to 12-month ECL(S1) | V3: + | X3: >= | Y3: -5 | Z3: <= | AA3: 5 | AG3: e | AH3: e
A4: Changed | B4: ACTIVE | C4: Loss allowance | E4: A029_09 | F4: =VLOOKUP(E4,Sheet2!$A:$A,1,FALSE) -> A029_09 | L4: A029_09 Transfer to lifetime ECL ToM should be total 0 | O4: 10891 | P4: Loss allow.stage1 -Am.Cost CDO/CLO | R4: 603 | S4: Transfer to lifetime ECL(S2) | V4: + | X4: >= | Y4: -5 | Z4: <= | AA4: 5 | AG4: e | AH4: e
A5: Changed | B5: ACTIVE | C5: Loss allowance | E5: A029_09 | F5: =VLOOKUP(E5,Sheet2!$A:$A,1,FALSE) -> A029_09 | L5: A029_09 Transfer to lifetime ECL ToM should be total 0 | O5: 10931 | P5: Loss allow.stage2 -Am.Cost CDO/CLO | R5: 603 | S5: Transfer to lifetime ECL(S2) | V5: + | X5: >= | Y5: -5 | Z5: <= | AA5: 5 | AG5: e | AH5: e
A6: Changed | B6: ACTIVE | C6: Equity Securities - Common Stock | E6: A079_00 | F6: =VLOOKUP(E6,Sheet2!$A:$A,1,FALSE) -> A079_00 | L6: A079_00 No pos. or neg. Diff. FV - to FVPL Equity sec. | O6: 12311 | P6: FVPL Comm.stocks-Publ.util.(SLST FV,LCM) | R6: 880 | S6: Inc m. val.chg in ex lifeFVOCI-bk. to eq | V6: + | X6: >= | Y6: -5 | Z6: <= | AA6: 5 | AD6: FS Item, ToM | AG6: e | AH6: e | AS6: e | CO6: w | CP6: w
A7: Changed | B7: ACTIVE | C7: Equity Securities - Common Stock | E7: A079_00 | F7: =VLOOKUP(E7,Sheet2!$A:$A,1,FALSE) -> A079_00 | L7: A079_00 No pos. or neg. Diff. FV - to FVPL Equity sec. | O7: 12311 | P7: FVPL Comm.stocks-Publ.util.(SLST FV,LCM) | R7: 882 | S7: Decr m. val/chg in exp life FVOCI bk t q | V7: + | X7: >= | Y7: -5 | Z7: <= | AA7: 5 | AD7: FS Item, ToM | AG7: e | AH7: e | AS7: e | CO7: w | CP7: w
A8: Changed | B8: ACTIVE | C8: Equity Securities - Common Stock | E8: A079_00 | F8: =VLOOKUP(E8,Sheet2!$A:$A,1,FALSE) -> A079_00 | L8: A079_00 No pos. or neg. Diff. FV - to FVPL Equity sec. | O8: 12321 | P8: FVPL Comm.st.-Banks,Ins&oth(SLST FV,LCM) | R8: 880 | S8: Inc m. val.chg in ex lifeFVOCI-bk. to eq | V8: + | X8: >= | Y8: -5 | Z8: <= | AA8: 5 | AD8: FS Item, ToM | AG8: e | AH8: e | AS8: e | CO8: w | CP8: w
A9: Changed | B9: ACTIVE | C9: Equity Securities - Common Stock | E9: A079_00 | F9: =VLOOKUP(E9,Sheet2!$A:$A,1,FALSE) -> A079_00 | L9: A079_00 No pos. or neg. Diff. FV - to FVPL Equity sec. | O9: 12321 | P9: FVPL Comm.st.-Banks,Ins&oth(SLST FV,LCM) | R9: 882 | S9: Decr m. val/chg in exp life FVOCI bk t q | V9: + | X9: >= | Y9: -5 | Z9: <= | AA9: 5 | AD9: FS Item, ToM | AG9: e | AH9: e | AS9: e | CO9: w | CP9: w
A10: Changed | B10: ACTIVE | C10: Equity Securities - Common Stock | E10: A079_00 | F10: =VLOOKUP(E10,Sheet2!$A:$A,1,FALSE) -> A079_00 | L10: A079_00 No pos. or neg. Diff. FV - to FVPL Equity sec. | O10: 12341 | P10: FVPL Com.stocks-ZIG(own shares,SLST FV) | R10: 880 | S10: Inc m. val.chg in ex lifeFVOCI-bk. to eq | V10: + | X10: >= | Y10: -5 | Z10: <= | AA10: 5 | AD10: FS Item, ToM | AG10: e | AH10: e | AS10: e | CO10: w | CP10: w
A11: Changed | B11: ACTIVE | C11: Equity Securities - Common Stock | E11: A079_00 | F11: =VLOOKUP(E11,Sheet2!$A:$A,1,FALSE) -> A079_00 | L11: A079_00 No pos. or neg. Diff. FV - to FVPL Equity sec. | O11: 12341 | P11: FVPL Com.stocks-ZIG(own shares,SLST FV) | R11: 882 | S11: Decr m. val/chg in exp life FVOCI bk t q | V11: + | X11: >= | Y11: -5 | Z11: <= | AA11: 5 | AD11: FS Item, ToM | AG11: e | AH11: e | AS11: e | CO11: w | CP11: w
A12: Changed | B12: ACTIVE | C12: Equity Securities - Common Stock | E12: A079_00 | F12: =VLOOKUP(E12,Sheet2!$A:$A,1,FALSE) -> A079_00 | L12: A079_00 No pos. or neg. Diff. FV - to FVPL Equity sec. | O12: 12361 | P12: FVPL Comm.st.-Industr&Misc(SLST FV,LCM) | R12: 880 | S12: Inc m. val.chg in ex lifeFVOCI-bk. to eq | V12: + | X12: >= | Y12: -5 | Z12: <= | AA12: 5 | AD12: FS Item, ToM | AG12: e | AH12: e | AS12: e | CO12: w | CP12: w
A13: Changed | B13: ACTIVE | C13: Equity Securities - Common Stock | E13: A079_00 | F13: =VLOOKUP(E13,Sheet2!$A:$A,1,FALSE) -> A079_00 | L13: A079_00 No pos. or neg. Diff. FV - to FVPL Equity sec. | O13: 12361 | P13: FVPL Comm.st.-Industr&Misc(SLST FV,LCM) | R13: 882 | S13: Decr m. val/chg in exp life FVOCI bk t q | V13: + | X13: >= | Y13: -5 | Z13: <= | AA13: 5 | AD13: FS Item, ToM | AG13: e | AH13: e | AS13: e | CO13: w | CP13: w
A14: Changed | B14: ACTIVE | C14: Equity Securities - Common Stock | E14: A079_00 | F14: =VLOOKUP(E14,Sheet2!$A:$A,1,FALSE) -> A079_00 | L14: A079_00 No pos. or neg. Diff. FV - to FVPL Equity sec. | O14: 12366 | P14: UL Common Stocks FVPL (SLST FV) | R14: 880 | S14: Inc m. val.chg in ex lifeFVOCI-bk. to eq | V14: + | X14: >= | Y14: -5 | Z14: <= | AA14: 5 | AD14: FS Item, ToM | AG14: e | AH14: e | AS14: e | CO14: w | CP14: w
A15: Changed | B15: ACTIVE | C15: Equity Securities - Common Stock | E15: A079_00 | F15: =VLOOKUP(E15,Sheet2!$A:$A,1,FALSE) -> A079_00 | L15: A079_00 No pos. or neg. Diff. FV - to FVPL Equity sec. | O15: 12366 | P15: UL Common Stocks FVPL (SLST FV) | R15: 882 | S15: Decr m. val/chg in exp life FVOCI bk t q | V15: + | X15: >= | Y15: -5 | Z15: <= | AA15: 5 | AD15: FS Item, ToM | AG15: e | AH15: e | AS15: e | CO15: w | CP15: w
A16: Changed | B16: ACTIVE | C16: Equity Securities - Common Stock | E16: A079_00 | F16: =VLOOKUP(E16,Sheet2!$A:$A,1,FALSE) -> A079_00 | L16: A079_00 No pos. or neg. Diff. FV - to FVPL Equity sec. | O16: 12371 | P16: FVPL Unlisted stocks (SLST LoCoM) | R16: 882 | S16: Decr m. val/chg in exp life FVOCI bk t q | V16: + | X16: >= | Y16: -5 | Z16: <= | AA16: 5 | AD16: FS Item, ToM | AG16: e | AH16: e | AS16: e | CO16: w | CP16: w
A17: Changed | B17: ACTIVE | C17: Equity Securities - Common Stock | E17: A079_00 | F17: =VLOOKUP(E17,Sheet2!$A:$A,1,FALSE) -> A079_00 | L17: A079_00 No pos. or neg. Diff. FV - to FVPL Equity sec. | O17: 12371 | P17: FVPL Unlisted stocks (SLST LoCoM) | R17: 880 | S17: Inc m. val.chg in ex lifeFVOCI-bk. to eq | V17: + | X17: >= | Y17: -5 | Z17: <= | AA17: 5 | AD17: FS Item, ToM | AG17: e | AH17: e | AS17: e | CO17: w | CP17: w
... A67: Changed | B67: ACTIVE | C67: Equity Securities - Open-end investment funds | E67: A091_00 | F67: =VLOOKUP(E67,Sheet2!$A:$A,1,FALSE) -> A091_00 | L67: A091_00 No neg Diff. FV on EQ for FVPL Open-end inv. funds | O67: 14386 | P67: UL OE inv.funds-Mixed-FVPL(SLST FV) | R67: 882 | S67: Decr m. val/chg in exp life FVOCI bk t q | V67: + | X67: >= | Y67: -5 | Z67: <= | AA67: 5 | AD67: FS Item | AG67: e | AH67: e | AS67: e | CO67: w | CP67: w
B68: ACTIVE | C68: Debt Securities - Amortized cost | E68: A102_00 | F68: =VLOOKUP(E68,Sheet2!$A:$A,1,FALSE) -> A102_00 | L68: A102_00 Transfers betw Investm. Classes - Amortized Cost - 3rd part | O68: 10151 | P68: Amortized Cost Bonds-Swiss Gov(SLST AC) | R68: 272 | S68: Transfers between types of instrum -Ded | V68: + | X68: >= | Y68: -5 | Z68: <= | AA68: 5 | AG68: e | AH68: e | AS68: e | CO68: w | CP68: w
B69: ACTIVE | C69: Debt Securities - Amortized cost | E69: A102_00 | F69: =VLOOKUP(E69,Sheet2!$A:$A,1,FALSE) -> A102_00 | L69: A102_00 Transfers betw Investm. Classes - Amortized Cost - 3rd part | O69: 10151 | P69: Amortized Cost Bonds-Swiss Gov(SLST AC) | R69: 270 | S69: Transfers between types of instrum - Add | V69: + | X69: >= | Y69: -5 | Z69: <= | AA69: 5 | AG69: e | AH69: e | AS69: e | CO69: w | CP69: w
B70: ACTIVE | C70: Debt Securities - Amortized cost | E70: A102_00 | F70: =VLOOKUP(E70,Sheet2!$A:$A,1,FALSE) -> A102_00 | L70: A102_00 Transfers betw Investm. Classes - Amortized Cost - 3rd part | O70: 10161 | P70: Amortized Cost Bonds-U.S. Gov(SLST AC) | R70: 270 | S70: Transfers between types of instrum - Add | V70: + | X70: >= | Y70: -5 | Z70: <= | AA70: 5 | AG70: e | AH70: e | AS70: e | CO70: w | CP70: w
B71: ACTIVE | C71: Debt Securities - Amortized cost | E71: A102_00 | F71: =VLOOKUP(E71,Sheet2!$A:$A,1,FALSE) -> A102_00 | L71: A102_00 Transfers betw Investm. Classes - Amortized Cost - 3rd part | O71: 10161 | P71: Amortized Cost Bonds-U.S. Gov(SLST AC) | R71: 272 | S71: Transfers between types of instrum -Ded | V71: + | X71: >= | Y71: -5 | Z71: <= | AA71: 5 | AG71: e | AH71: e | AS71: e | CO71: w | CP71: w
B72: ACTIVE | C72: Debt Securities - Amortized cost | E72: A102_00 | F72: =VLOOKUP(E72,Sheet2!$A:$A,1,FALSE) -> A102_00 | L72: A102_00 Transfers betw Investm. Classes - Amortized Cost - 3rd part | O72: 10171 | P72: Amortized Cost Bonds-Other Govs(SLST AC) | R72: 270 | S72: Transfers between types of instrum - Add | V72: + | X72: >= | Y72: -5 | Z72: <= | AA72: 5 | AG72: e | AH72: e | AS72: e | CO72: w | CP72: w
B73: ACTIVE | C73: Debt Securities - Amortized cost | E73: A102_00 | F73: =VLOOKUP(E73,Sheet2!$A:$A,1,FALSE) -> A102_00 | L73: A102_00 Transfers betw Investm. Classes - Amortized Cost - 3rd part | O73: 10171 | P73: Amortized Cost Bonds-Other Govs(SLST AC) | R73: 272 | S73: Transfers between types of instrum -Ded | V73: + | X73: >= | Y73: -5 | Z73: <= | AA73: 5 | AG73: e | AH73: e | AS73: e | CO73: w | CP73: w
B74: ACTIVE | C74: Debt Securities - Amortized cost | E74: A102_00 | F74: =VLOOKUP(E74,Sheet2!$A:$A,1,FALSE) -> A102_00 | L74: A102_00 Transfers betw Investm. Classes - Amortized Cost - 3rd part | O74: 10181 | P74: Amortized Cost Bonds-U.K. Gov(SLST AC) | R74: 270 | S74: Transfers between types of instrum - Add | V74: + | X74: >= | Y74: -5 | Z74: <= | AA74: 5 | AG74: e | AH74: e | AS74: e | CO74: w | CP74: w
B75: ACTIVE | C75: Debt Securities - Amortized cost | E75: A102_00 | F75: =VLOOKUP(E75,Sheet2!$A:$A,1,FALSE) -> A102_00 | L75: A102_00 Transfers betw Investm. Classes - Amortized Cost - 3rd part | O75: 10181 | P75: Amortized Cost Bonds-U.K. Gov(SLST AC) | R75: 272 | S75: Transfers between types of instrum -Ded | V75: + | X75: >= | Y75: -5 | Z75: <= | AA75: 5 | AG75: e | AH75: e | AS75: e | CO75: w | CP75: w
B76: ACTIVE | C76: Debt Securities - Amortized cost | E76: A102_00 | F76: =VLOOKUP(E76,Sheet2!$A:$A,1,FALSE) -> A102_00 | L76: A102_00 Transfers betw Investm. Classes - Amortized Cost - 3rd part | O76: 10191 | P76: Amort.Cost Bonds-Public Utilit.(SLST AC) | R76: 272 | S76: Transfers between types of instrum -Ded | V76: + | X76: >= | Y76: -5 | Z76: <= | AA76: 5 | AG76: e | AH76: e | AS76: e | CO76: w | CP76: w
B77: ACTIVE | C77: Debt Securities - Amortized cost | E77: A102_00 | F77: =VLOOKUP(E77,Sheet2!$A:$A,1,FALSE) -> A102_00 | L77: A102_00 Transfers betw Investm. Classes - Amortized Cost - 3rd part | O77: 10191 | P77: Amort.Cost Bonds-Public Utilit.(SLST AC) | R77: 270 | S77: Transfers between types of instrum - Add | V77: + | X77: >= | Y77: -5 | Z77: <= | AA77: 5 | AG77: e | AH77: e | AS77: e | CO77: w | CP77: w
B78: ACTIVE | C78: Debt Securities - Amortized cost | E78: A102_00 | F78: =VLOOKUP(E78,Sheet2!$A:$A,1,FALSE) -> A102_00 | L78: A102_00 Transfers betw Investm. Classes - Amortized Cost - 3rd part | O78: 10221 | P78: Amortized Cost Bonds-Corporates(SLST AC) | R78: 270 | S78: Transfers between types of instrum - Add | V78: + | X78: >= | Y78: -5 | Z78: <= | AA78: 5 | AG78: e | AH78: e | AS78: e | CO78: w | CP78: w
B79: ACTIVE | C79: Debt Securities - Amortized cost | E79: A102_00 | F79: =VLOOKUP(E79,Sheet2!$A:$A,1,FALSE) -> A102_00 | L79: A102_00 Transfers betw Investm. Classes - Amortized Cost - 3rd part | O79: 10221 | P79: Amortized Cost Bonds-Corporates(SLST AC) | R79: 272 | S79: Transfers between types of instrum -Ded | V79: + | X79: >= | Y79: -5 | Z79: <= | AA79: 5 | AG79: e | AH79: e | AS79: e | CO79: w | CP79: w
... B85: ACTIVE | C85: Debt Securities - Amortized cost | E85: A102_00 | F85: =VLOOKUP(E85,Sheet2!$A:$A,1,FALSE) -> A102_00 | L85: A102_00 Transfers betw Investm. Classes - Amortized Cost - 3rd part | O85: 10461 | P85: Amort.Cost Bonds-Private Debt(SLST AC) | R85: 270 | S85: Transfers between types of instrum - Add | V85: + | X85: >= | Y85: -5 | Z85: <= | AA85: 5 | AG85: e | AH85: e | AS85: e | CO85: w | CP85: w
B86: ACTIVE | C86: FVPL debts | D86: yes | E86: A114_00 | F86: =VLOOKUP(E86,Sheet2!$A:$A,1,FALSE) -> A114_00 | L86: A114_00 Transfers betw Investm. Classes-FVPL-3rd part | O86: 10251 | P86: FVPL Bonds-Swiss Gov FV Option(SLST AC) | R86: 270 | S86: Transfers between types of instrum - Add | V86: + | X86: >= | Y86: -5 | Z86: <= | AA86: 5 | AG86: w | AH86: w | AS86: w | CO86: w | CP86: w
B87: ACTIVE | C87: FVPL debts | D87: yes | E87: A114_00 | F87: =VLOOKUP(E87,Sheet2!$A:$A,1,FALSE) -> A114_00 | L87: A114_00 Transfers betw Investm. Classes-FVPL-3rd part | O87: 10251 | P87: FVPL Bonds-Swiss Gov FV Option(SLST AC) | R87: 272 | S87: Transfers between types of instrum -Ded | V87: + | X87: >= | Y87: -5 | Z87: <= | AA87: 5 | AG87: w | AH87: w | AS87: w | CO87: w | CP87: w
B88: ACTIVE | C88: FVPL debts | D88: yes | E88: A114_00 | F88: =VLOOKUP(E88,Sheet2!$A:$A,1,FALSE) -> A114_00 | L88: A114_00 Transfers betw Investm. Classes-FVPL-3rd part | O88: 10261 | P88: FVPL Bonds-U.S. Gov FV Option(SLST AC) | R88: 272 | S88: Transfers between types of instrum -Ded | V88: + | X88: >= | Y88: -5 | Z88: <= | AA88: 5 | AG88: w | AH88: w | AS88: w | CO88: w | CP88: w
B89: ACTIVE | C89: FVPL debts | D89: yes | E89: A114_00 | F89: =VLOOKUP(E89,Sheet2!$A:$A,1,FALSE) -> A114_00 | L89: A114_00 Transfers betw Investm. Classes-FVPL-3rd part | O89: 10261 | P89: FVPL Bonds-U.S. Gov FV Option(SLST AC) | R89: 270 | S89: Transfers between types of instrum - Add | V89: + | X89: >= | Y89: -5 | Z89: <= | AA89: 5 | AG89: w | AH89: w | AS89: w | CO89: w | CP89: w
B90: ACTIVE | C90: FVPL debts | D90: yes | E90: A114_00 | F90: =VLOOKUP(E90,Sheet2!$A:$A,1,FALSE) -> A114_00 | L90: A114_00 Transfers betw Investm. Classes-FVPL-3rd part | O90: 10271 | P90: FVPL Bonds-Other Gov. FV Option(SLST AC) | R90: 272 | S90: Transfers between types of instrum -Ded | V90: + | X90: >= | Y90: -5 | Z90: <= | AA90: 5 | AG90: w | AH90: w | AS90: w | CO90: w | CP90: w
B91: ACTIVE | C91: FVPL debts | D91: yes | E91: A114_00 | F91: =VLOOKUP(E91,Sheet2!$A:$A,1,FALSE) -> A114_00 | L91: A114_00 Transfers betw Investm. Classes-FVPL-3rd part | O91: 10271 | P91: FVPL Bonds-Other Gov. FV Option(SLST AC) | R91: 270 | S91: Transfers between types of instrum - Add | V91: + | X91: >= | Y91: -5 | Z91: <= | AA91: 5 | AG91: w | AH91: w | AS91: w | CO91: w | CP91: w
B92: ACTIVE | C92: FVPL debts | D92: yes | E92: A114_00 | F92: =VLOOKUP(E92,Sheet2!$A:$A,1,FALSE) -> A114_00 | L92: A114_00 Transfers betw Investm. Classes-FVPL-3rd part | O92: 10281 | P92: FVPL Bonds-U.K. Gov FV Option(SLST AC) | R92: 272 | S92: Transfers between types of instrum -Ded | V92: + | X92: >= | Y92: -5 | Z92: <= | AA92: 5 | AG92: w | AH92: w | AS92: w | CO92: w | CP92: w
B93: ACTIVE | C93: FVPL debts | D93: yes | E93: A114_00 | F93: =VLOOKUP(E93,Sheet2!$A:$A,1,FALSE) -> A114_00 | L93: A114_00 Transfers betw Investm. Classes-FVPL-3rd part | O93: 10281 | P93: FVPL Bonds-U.K. Gov FV Option(SLST AC) | R93: 270 | S93: Transfers between types of instrum - Add | V93: + | X93: >= | Y93: -5 | Z93: <= | AA93: 5 | AG93: w | AH93: w | AS93: w | CO93: w | CP93: w
B94: ACTIVE | C94: FVPL debts | D94: yes | E94: A114_00 | F94: =VLOOKUP(E94,Sheet2!$A:$A,1,FALSE) -> A114_00 | L94: A114_00 Transfers betw Investm. Classes-FVPL-3rd part | O94: 10291 | P94: FVPL Bonds-Public Utilit FV Opt(SLST AC) | R94: 270 | S94: Transfers between types of instrum - Add | V94: + | X94: >= | Y94: -5 | Z94: <= | AA94: 5 | AG94: w | AH94: w | AS94: w | CO94: w | CP94: w
...

Sheet Sheet2
A1: X-Check No.
A2: A011_09
A3: A029_09
A4: A079_00
A5: A090_00
A6: A091_00
A7: A114_00
A8: A137_00
A9: A147_00
A10: A152_00
A11: A153_00
A12: A159_09
... A203: AR033_00
