Workbook

Sheet cross checks all
A1: Type of change | B1: Status | C1: Category | D1: Sense Check | E1: X-Check No. | F1: Reference X-Check (Condition) | G1: Applicable Quarters | H1: Included RUs | I1: Excluded RUs | J1: Reference X-Check (Limit, %) | Q1: =SUM(Q2:Q1893) -> 0 | R1: =SUM(R2:R1893) -> 19 | S1: =SUM(S2:S1893) -> 0 | T1: =SUM(T2:T1893) -> 0 | U1: =SUM(U2:U1893) -> 0
A2: Changed | B2: ACTIVE | C2: Real Estate held for Investment | E2: A047_00 | K2: =IFERROR(VLOOKUP($E2 & "|" & F2,comparison!$A$2:$A$19,1,FALSE),"") | L2: =IFERROR(VLOOKUP($E2 & "|" & G2,comparison!$A$2:$A$19,1,FALSE),"") | M2: =IFERROR(VLOOKUP($E2 & "|" & H2,comparison!$A$2:$A$19,1,FALSE),"") | N2: =IFERROR(VLOOKUP($E2 & "|" & I2,comparison!$A$2:$A$19,1,FALSE),"") | O2: =IFERROR(VLOOKUP($E2 & "|" & J2,comparison!$A$2:$A$19,1,FALSE),"") | Q2: =IF(LEN(K2)>0,1,0) -> 0 | R2: =IF(LEN(L2)>0,1,0) -> 0 | S2: =IF(LEN(M2)>0,1,0) -> 0 | T2: =IF(LEN(N2)>0,1,0) -> 0 | U2: =IF(LEN(O2)>0,1,0) -> 0
A3: Changed | B3: ACTIVE | C3: Equity Securities - Common Stock | D3: yes | E3: A074_00 | K3: =IFERROR(VLOOKUP($E3 & "|" & F3,comparison!$A$2:$A$19,1,FALSE),"") | L3: =IFERROR(VLOOKUP($E3 & "|" & G3,comparison!$A$2:$A$19,1,FALSE),"") | M3: =IFERROR(VLOOKUP($E3 & "|" & H3,comparison!$A$2:$A$19,1,FALSE),"") | N3: =IFERROR(VLOOKUP($E3 & "|" & I3,comparison!$A$2:$A$19,1,FALSE),"") | O3: =IFERROR(VLOOKUP($E3 & "|" & J3,comparison!$A$2:$A$19,1,FALSE),"") | Q3: =IF(LEN(K3)>0,1,0) -> 0 | R3: =IF(LEN(L3)>0,1,0) -> 0 | S3: =IF(LEN(M3)>0,1,0) -> 0 | T3: =IF(LEN(N3)>0,1,0) -> 0 | U3: =IF(LEN(O3)>0,1,0) -> 0
A4: Changed | B4: ACTIVE | C4: Equity Securities - Common Stock | E4: A079_00 | K4: =IFERROR(VLOOKUP($E4 & "|" & F4,comparison!$A$2:$A$19,1,FALSE),"") | L4: =IFERROR(VLOOKUP($E4 & "|" & G4,comparison!$A$2:$A$19,1,FALSE),"") | M4: =IFERROR(VLOOKUP($E4 & "|" & H4,comparison!$A$2:$A$19,1,FALSE),"") | N4: =IFERROR(VLOOKUP($E4 & "|" & I4,comparison!$A$2:$A$19,1,FALSE),"") | O4: =IFERROR(VLOOKUP($E4 & "|" & J4,comparison!$A$2:$A$19,1,FALSE),"") | Q4: =IF(LEN(K4)>0,1,0) -> 0 | R4: =IF(LEN(L4)>0,1,0) -> 0 | S4: =IF(LEN(M4)>0,1,0) -> 0 | T4: =IF(LEN(N4)>0,1,0) -> 0 | U4: =IF(LEN(O4)>0,1,0) -> 0
A5: Changed | B5: ACTIVE | C5: Equity Securities - Common Stock | E5: A081_00 | K5: =IFERROR(VLOOKUP($E5 & "|" & F5,comparison!$A$2:$A$19,1,FALSE),"") | L5: =IFERROR(VLOOKUP($E5 & "|" & G5,comparison!$A$2:$A$19,1,FALSE),"") | M5: =IFERROR(VLOOKUP($E5 & "|" & H5,comparison!$A$2:$A$19,1,FALSE),"") | N5: =IFERROR(VLOOKUP($E5 & "|" & I5,comparison!$A$2:$A$19,1,FALSE),"") | O5: =IFERROR(VLOOKUP($E5 & "|" & J5,comparison!$A$2:$A$19,1,FALSE),"") | Q5: =IF(LEN(K5)>0,1,0) -> 0 | R5: =IF(LEN(L5)>0,1,0) -> 0 | S5: =IF(LEN(M5)>0,1,0) -> 0 | T5: =IF(LEN(N5)>0,1,0) -> 0 | U5: =IF(LEN(O5)>0,1,0) -> 0
A6: Changed | B6: ACTIVE | C6: Equity Securities - Common Stock | D6: yes | E6: A082_00 | K6: =IFERROR(VLOOKUP($E6 & "|" & F6,comparison!$A$2:$A$19,1,FALSE),"") | L6: =IFERROR(VLOOKUP($E6 & "|" & G6,comparison!$A$2:$A$19,1,FALSE),"") | M6: =IFERROR(VLOOKUP($E6 & "|" & H6,comparison!$A$2:$A$19,1,FALSE),"") | N6: =IFERROR(VLOOKUP($E6 & "|" & I6,comparison!$A$2:$A$19,1,FALSE),"") | O6: =IFERROR(VLOOKUP($E6 & "|" & J6,comparison!$A$2:$A$19,1,FALSE),"") | Q6: =IF(LEN(K6)>0,1,0) -> 0 | R6: =IF(LEN(L6)>0,1,0) -> 0 | S6: =IF(LEN(M6)>0,1,0) -> 0 | T6: =IF(LEN(N6)>0,1,0) -> 0 | U6: =IF(LEN(O6)>0,1,0) -> 0
A7: Changed | B7: ACTIVE | C7: Equity Securities - Open-end investment funds | E7: A090_00 | K7: =IFERROR(VLOOKUP($E7 & "|" & F7,comparison!$A$2:$A$19,1,FALSE),"") | L7: =IFERROR(VLOOKUP($E7 & "|" & G7,comparison!$A$2:$A$19,1,FALSE),"") | M7: =IFERROR(VLOOKUP($E7 & "|" & H7,comparison!$A$2:$A$19,1,FALSE),"") | N7: =IFERROR(VLOOKUP($E7 & "|" & I7,comparison!$A$2:$A$19,1,FALSE),"") | O7: =IFERROR(VLOOKUP($E7 & "|" & J7,comparison!$A$2:$A$19,1,FALSE),"") | Q7: =IF(LEN(K7)>0,1,0) -> 0 | R7: =IF(LEN(L7)>0,1,0) -> 0 | S7: =IF(LEN(M7)>0,1,0) -> 0 | T7: =IF(LEN(N7)>0,1,0) -> 0 | U7: =IF(LEN(O7)>0,1,0) -> 0
A8: Changed | B8: ACTIVE | C8: Equity Securities - Open-end investment funds | E8: A091_00 | K8: =IFERROR(VLOOKUP($E8 & "|" & F8,comparison!$A$2:$A$19,1,FALSE),"") | L8: =IFERROR(VLOOKUP($E8 & "|" & G8,comparison!$A$2:$A$19,1,FALSE),"") | M8: =IFERROR(VLOOKUP($E8 & "|" & H8,comparison!$A$2:$A$19,1,FALSE),"") | N8: =IFERROR(VLOOKUP($E8 & "|" & I8,comparison!$A$2:$A$19,1,FALSE),"") | O8: =IFERROR(VLOOKUP($E8 & "|" & J8,comparison!$A$2:$A$19,1,FALSE),"") | Q8: =IF(LEN(K8)>0,1,0) -> 0 | R8: =IF(LEN(L8)>0,1,0) -> 0 | S8: =IF(LEN(M8)>0,1,0) -> 0 | T8: =IF(LEN(N8)>0,1,0) -> 0 | U8: =IF(LEN(O8)>0,1,0) -> 0
A9: Changed | B9: ACTIVE | C9: Equity Securities - Open-end investment funds | D9: yes | E9: A094_00 | K9: =IFERROR(VLOOKUP($E9 & "|" & F9,comparison!$A$2:$A$19,1,FALSE),"") | L9: =IFERROR(VLOOKUP($E9 & "|" & G9,comparison!$A$2:$A$19,1,FALSE),"") | M9: =IFERROR(VLOOKUP($E9 & "|" & H9,comparison!$A$2:$A$19,1,FALSE),"") | N9: =IFERROR(VLOOKUP($E9 & "|" & I9,comparison!$A$2:$A$19,1,FALSE),"") | O9: =IFERROR(VLOOKUP($E9 & "|" & J9,comparison!$A$2:$A$19,1,FALSE),"") | Q9: =IF(LEN(K9)>0,1,0) -> 0 | R9: =IF(LEN(L9)>0,1,0) -> 0 | S9: =IF(LEN(M9)>0,1,0) -> 0 | T9: =IF(LEN(N9)>0,1,0) -> 0 | U9: =IF(LEN(O9)>0,1,0) -> 0
A10: Changed | B10: ACTIVE | C10: Equity Securities - Open-end investment funds | E10: A096_00 | K10: =IFERROR(VLOOKUP($E10 & "|" & F10,comparison!$A$2:$A$19,1,FALSE),"") | L10: =IFERROR(VLOOKUP($E10 & "|" & G10,comparison!$A$2:$A$19,1,FALSE),"") | M10: =IFERROR(VLOOKUP($E10 & "|" & H10,comparison!$A$2:$A$19,1,FALSE),"") | N10: =IFERROR(VLOOKUP($E10 & "|" & I10,comparison!$A$2:$A$19,1,FALSE),"") | O10: =IFERROR(VLOOKUP($E10 & "|" & J10,comparison!$A$2:$A$19,1,FALSE),"") | Q10: =IF(LEN(K10)>0,1,0) -> 0 | R10: =IF(LEN(L10)>0,1,0) -> 0 | S10: =IF(LEN(M10)>0,1,0) -> 0 | T10: =IF(LEN(N10)>0,1,0) -> 0 | U10: =IF(LEN(O10)>0,1,0) -> 0
A11: Changed | B11: ACTIVE | C11: Debt Securities - FVOCI | E11: A101_00 | K11: =IFERROR(VLOOKUP($E11 & "|" & F11,comparison!$A$2:$A$19,1,FALSE),"") | L11: =IFERROR(VLOOKUP($E11 & "|" & G11,comparison!$A$2:$A$19,1,FALSE),"") | M11: =IFERROR(VLOOKUP($E11 & "|" & H11,comparison!$A$2:$A$19,1,FALSE),"") | N11: =IFERROR(VLOOKUP($E11 & "|" & I11,comparison!$A$2:$A$19,1,FALSE),"") | O11: =IFERROR(VLOOKUP($E11 & "|" & J11,comparison!$A$2:$A$19,1,FALSE),"") | Q11: =IF(LEN(K11)>0,1,0) -> 0 | R11: =IF(LEN(L11)>0,1,0) -> 0 | S11: =IF(LEN(M11)>0,1,0) -> 0 | T11: =IF(LEN(N11)>0,1,0) -> 0 | U11: =IF(LEN(O11)>0,1,0) -> 0
A12: Changed | B12: ACTIVE | C12: Debt Securities - Amortized cost | E12: A102_00 | K12: =IFERROR(VLOOKUP($E12 & "|" & F12,comparison!$A$2:$A$19,1,FALSE),"") | L12: =IFERROR(VLOOKUP($E12 & "|" & G12,comparison!$A$2:$A$19,1,FALSE),"") | M12: =IFERROR(VLOOKUP($E12 & "|" & H12,comparison!$A$2:$A$19,1,FALSE),"") | N12: =IFERROR(VLOOKUP($E12 & "|" & I12,comparison!$A$2:$A$19,1,FALSE),"") | O12: =IFERROR(VLOOKUP($E12 & "|" & J12,comparison!$A$2:$A$19,1,FALSE),"") | Q12: =IF(LEN(K12)>0,1,0) -> 0 | R12: =IF(LEN(L12)>0,1,0) -> 0 | S12: =IF(LEN(M12)>0,1,0) -> 0 | T12: =IF(LEN(N12)>0,1,0) -> 0 | U12: =IF(LEN(O12)>0,1,0) -> 0
A13: Changed | B13: ACTIVE | C13: FVPL debts | D13: yes | E13: A114_00 | K13: =IFERROR(VLOOKUP($E13 & "|" & F13,comparison!$A$2:$A$19,1,FALSE),"") | L13: =IFERROR(VLOOKUP($E13 & "|" & G13,comparison!$A$2:$A$19,1,FALSE),"") | M13: =IFERROR(VLOOKUP($E13 & "|" & H13,comparison!$A$2:$A$19,1,FALSE),"") | N13: =IFERROR(VLOOKUP($E13 & "|" & I13,comparison!$A$2:$A$19,1,FALSE),"") | O13: =IFERROR(VLOOKUP($E13 & "|" & J13,comparison!$A$2:$A$19,1,FALSE),"") | Q13: =IF(LEN(K13)>0,1,0) -> 0 | R13: =IF(LEN(L13)>0,1,0) -> 0 | S13: =IF(LEN(M13)>0,1,0) -> 0 | T13: =IF(LEN(N13)>0,1,0) -> 0 | U13: =IF(LEN(O13)>0,1,0) -> 0
A14: Changed | B14: ACTIVE | C14: Real Estate held for Investment | E14: A137_00 | K14: =IFERROR(VLOOKUP($E14 & "|" & F14,comparison!$A$2:$A$19,1,FALSE),"") | L14: =IFERROR(VLOOKUP($E14 & "|" & G14,comparison!$A$2:$A$19,1,FALSE),"") | M14: =IFERROR(VLOOKUP($E14 & "|" & H14,comparison!$A$2:$A$19,1,FALSE),"") | N14: =IFERROR(VLOOKUP($E14 & "|" & I14,comparison!$A$2:$A$19,1,FALSE),"") | O14: =IFERROR(VLOOKUP($E14 & "|" & J14,comparison!$A$2:$A$19,1,FALSE),"") | Q14: =IF(LEN(K14)>0,1,0) -> 0 | R14: =IF(LEN(L14)>0,1,0) -> 0 | S14: =IF(LEN(M14)>0,1,0) -> 0 | T14: =IF(LEN(N14)>0,1,0) -> 0 | U14: =IF(LEN(O14)>0,1,0) -> 0
A15: Changed | B15: ACTIVE | C15: Real Estate held for Investment | E15: A138_00 | K15: =IFERROR(VLOOKUP($E15 & "|" & F15,comparison!$A$2:$A$19,1,FALSE),"") | L15: =IFERROR(VLOOKUP($E15 & "|" & G15,comparison!$A$2:$A$19,1,FALSE),"") | M15: =IFERROR(VLOOKUP($E15 & "|" & H15,comparison!$A$2:$A$19,1,FALSE),"") | N15: =IFERROR(VLOOKUP($E15 & "|" & I15,comparison!$A$2:$A$19,1,FALSE),"") | O15: =IFERROR(VLOOKUP($E15 & "|" & J15,comparison!$A$2:$A$19,1,FALSE),"") | Q15: =IF(LEN(K15)>0,1,0) -> 0 | R15: =IF(LEN(L15)>0,1,0) -> 0 | S15: =IF(LEN(M15)>0,1,0) -> 0 | T15: =IF(LEN(N15)>0,1,0) -> 0 | U15: =IF(LEN(O15)>0,1,0) -> 0
A16: Changed | B16: ACTIVE | C16: Real Estate held for Investment | E16: A139_00 | K16: =IFERROR(VLOOKUP($E16 & "|" & F16,comparison!$A$2:$A$19,1,FALSE),"") | L16: =IFERROR(VLOOKUP($E16 & "|" & G16,comparison!$A$2:$A$19,1,FALSE),"") | M16: =IFERROR(VLOOKUP($E16 & "|" & H16,comparison!$A$2:$A$19,1,FALSE),"") | N16: =IFERROR(VLOOKUP($E16 & "|" & I16,comparison!$A$2:$A$19,1,FALSE),"") | O16: =IFERROR(VLOOKUP($E16 & "|" & J16,comparison!$A$2:$A$19,1,FALSE),"") | Q16: =IF(LEN(K16)>0,1,0) -> 0 | R16: =IF(LEN(L16)>0,1,0) -> 0 | S16: =IF(LEN(M16)>0,1,0) -> 0 | T16: =IF(LEN(N16)>0,1,0) -> 0 | U16: =IF(LEN(O16)>0,1,0) -> 0
A17: Changed | B17: ACTIVE | C17: Equity Securities - Non-redeemable Pref. Shares | E17: A152_00 | K17: =IFERROR(VLOOKUP($E17 & "|" & F17,comparison!$A$2:$A$19,1,FALSE),"") | L17: =IFERROR(VLOOKUP($E17 & "|" & G17,comparison!$A$2:$A$19,1,FALSE),"") | M17: =IFERROR(VLOOKUP($E17 & "|" & H17,comparison!$A$2:$A$19,1,FALSE),"") | N17: =IFERROR(VLOOKUP($E17 & "|" & I17,comparison!$A$2:$A$19,1,FALSE),"") | O17: =IFERROR(VLOOKUP($E17 & "|" & J17,comparison!$A$2:$A$19,1,FALSE),"") | Q17: =IF(LEN(K17)>0,1,0) -> 0 | R17: =IF(LEN(L17)>0,1,0) -> 0 | S17: =IF(LEN(M17)>0,1,0) -> 0 | T17: =IF(LEN(N17)>0,1,0) -> 0 | U17: =IF(LEN(O17)>0,1,0) -> 0
A18: Changed | B18: ACTIVE | C18: Equity Securities - Non-redeemable Pref. Shares | E18: A153_00 | K18: =IFERROR(VLOOKUP($E18 & "|" & F18,comparison!$A$2:$A$19,1,FALSE),"") | L18: =IFERROR(VLOOKUP($E18 & "|" & G18,comparison!$A$2:$A$19,1,FALSE),"") | M18: =IFERROR(VLOOKUP($E18 & "|" & H18,comparison!$A$2:$A$19,1,FALSE),"") | N18: =IFERROR(VLOOKUP($E18 & "|" & I18,comparison!$A$2:$A$19,1,FALSE),"") | O18: =IFERROR(VLOOKUP($E18 & "|" & J18,comparison!$A$2:$A$19,1,FALSE),"") | Q18: =IF(LEN(K18)>0,1,0) -> 0 | R18: =IF(LEN(L18)>0,1,0) -> 0 | S18: =IF(LEN(M18)>0,1,0) -> 0 | T18: =IF(LEN(N18)>0,1,0) -> 0 | U18: =IF(LEN(O18)>0,1,0) -> 0
A19: Changed | B19: ACTIVE | C19: Equity Securities - Non-redeemable Pref. Shares | E19: A158_00 | K19: =IFERROR(VLOOKUP($E19 & "|" & F19,comparison!$A$2:$A$19,1,FALSE),"") | L19: =IFERROR(VLOOKUP($E19 & "|" & G19,comparison!$A$2:$A$19,1,FALSE),"") | M19: =IFERROR(VLOOKUP($E19 & "|" & H19,comparison!$A$2:$A$19,1,FALSE),"") | N19: =IFERROR(VLOOKUP($E19 & "|" & I19,comparison!$A$2:$A$19,1,FALSE),"") | O19: =IFERROR(VLOOKUP($E19 & "|" & J19,comparison!$A$2:$A$19,1,FALSE),"") | Q19: =IF(LEN(K19)>0,1,0) -> 0 | R19: =IF(LEN(L19)>0,1,0) -> 0 | S19: =IF(LEN(M19)>0,1,0) -> 0 | T19: =IF(LEN(N19)>0,1,0) -> 0 | U19: =IF(LEN(O19)>0,1,0) -> 0
A20: Changed | B20: ACTIVE | C20: Loans and Receivables | D20: yes | E20: A171_00 | K20: =IFERROR(VLOOKUP($E20 & "|" & F20,comparison!$A$2:$A$19,1,FALSE),"") | L20: =IFERROR(VLOOKUP($E20 & "|" & G20,comparison!$A$2:$A$19,1,FALSE),"") | M20: =IFERROR(VLOOKUP($E20 & "|" & H20,comparison!$A$2:$A$19,1,FALSE),"") | N20: =IFERROR(VLOOKUP($E20 & "|" & I20,comparison!$A$2:$A$19,1,FALSE),"") | O20: =IFERROR(VLOOKUP($E20 & "|" & J20,comparison!$A$2:$A$19,1,FALSE),"") | Q20: =IF(LEN(K20)>0,1,0) -> 0 | R20: =IF(LEN(L20)>0,1,0) -> 0 | S20: =IF(LEN(M20)>0,1,0) -> 0 | T20: =IF(LEN(N20)>0,1,0) -> 0 | U20: =IF(LEN(O20)>0,1,0) -> 0
A21: Changed | B21: ACTIVE | C21: Holdings in affiliates | E21: A336_00 | K21: =IFERROR(VLOOKUP($E21 & "|" & F21,comparison!$A$2:$A$19,1,FALSE),"") | L21: =IFERROR(VLOOKUP($E21 & "|" & G21,comparison!$A$2:$A$19,1,FALSE),"") | M21: =IFERROR(VLOOKUP($E21 & "|" & H21,comparison!$A$2:$A$19,1,FALSE),"") | N21: =IFERROR(VLOOKUP($E21 & "|" & I21,comparison!$A$2:$A$19,1,FALSE),"") | O21: =IFERROR(VLOOKUP($E21 & "|" & J21,comparison!$A$2:$A$19,1,FALSE),"") | Q21: =IF(LEN(K21)>0,1,0) -> 0 | R21: =IF(LEN(L21)>0,1,0) -> 0 | S21: =IF(LEN(M21)>0,1,0) -> 0 | T21: =IF(LEN(N21)>0,1,0) -> 0 | U21: =IF(LEN(O21)>0,1,0) -> 0
A22: Changed | B22: ACTIVE | C22: IFRS 16 | E22: A369_00 | K22: =IFERROR(VLOOKUP($E22 & "|" & F22,comparison!$A$2:$A$19,1,FALSE),"") | L22: =IFERROR(VLOOKUP($E22 & "|" & G22,comparison!$A$2:$A$19,1,FALSE),"") | M22: =IFERROR(VLOOKUP($E22 & "|" & H22,comparison!$A$2:$A$19,1,FALSE),"") | N22: =IFERROR(VLOOKUP($E22 & "|" & I22,comparison!$A$2:$A$19,1,FALSE),"") | O22: =IFERROR(VLOOKUP($E22 & "|" & J22,comparison!$A$2:$A$19,1,FALSE),"") | Q22: =IF(LEN(K22)>0,1,0) -> 0 | R22: =IF(LEN(L22)>0,1,0) -> 0 | S22: =IF(LEN(M22)>0,1,0) -> 0 | T22: =IF(LEN(N22)>0,1,0) -> 0 | U22: =IF(LEN(O22)>0,1,0) -> 0
A23: Changed | B23: ACTIVE | C23: IFRS 16 | E23: A370_00 | K23: =IFERROR(VLOOKUP($E23 & "|" & F23,comparison!$A$2:$A$19,1,FALSE),"") | L23: =IFERROR(VLOOKUP($E23 & "|" & G23,comparison!$A$2:$A$19,1,FALSE),"") | M23: =IFERROR(VLOOKUP($E23 & "|" & H23,comparison!$A$2:$A$19,1,FALSE),"") | N23: =IFERROR(VLOOKUP($E23 & "|" & I23,comparison!$A$2:$A$19,1,FALSE),"") | O23: =IFERROR(VLOOKUP($E23 & "|" & J23,comparison!$A$2:$A$19,1,FALSE),"") | Q23: =IF(LEN(K23)>0,1,0) -> 0 | R23: =IF(LEN(L23)>0,1,0) -> 0 | S23: =IF(LEN(M23)>0,1,0) -> 0 | T23: =IF(LEN(N23)>0,1,0) -> 0 | U23: =IF(LEN(O23)>0,1,0) -> 0
A24: Changed | B24: ACTIVE | C24: IFRS 16 | E24: A371_00 | K24: =IFERROR(VLOOKUP($E24 & "|" & F24,comparison!$A$2:$A$19,1,FALSE),"") | L24: =IFERROR(VLOOKUP($E24 & "|" & G24,comparison!$A$2:$A$19,1,FALSE),"") | M24: =IFERROR(VLOOKUP($E24 & "|" & H24,comparison!$A$2:$A$19,1,FALSE),"") | N24: =IFERROR(VLOOKUP($E24 & "|" & I24,comparison!$A$2:$A$19,1,FALSE),"") | O24: =IFERROR(VLOOKUP($E24 & "|" & J24,comparison!$A$2:$A$19,1,FALSE),"") | Q24: =IF(LEN(K24)>0,1,0) -> 0 | R24: =IF(LEN(L24)>0,1,0) -> 0 | S24: =IF(LEN(M24)>0,1,0) -> 0 | T24: =IF(LEN(N24)>0,1,0) -> 0 | U24: =IF(LEN(O24)>0,1,0) -> 0
A25: Changed | B25: ACTIVE | C25: Fixed Assets | E25: A400_00 | K25: =IFERROR(VLOOKUP($E25 & "|" & F25,comparison!$A$2:$A$19,1,FALSE),"") | L25: =IFERROR(VLOOKUP($E25 & "|" & G25,comparison!$A$2:$A$19,1,FALSE),"") | M25: =IFERROR(VLOOKUP($E25 & "|" & H25,comparison!$A$2:$A$19,1,FALSE),"") | N25: =IFERROR(VLOOKUP($E25 & "|" & I25,comparison!$A$2:$A$19,1,FALSE),"") | O25: =IFERROR(VLOOKUP($E25 & "|" & J25,comparison!$A$2:$A$19,1,FALSE),"") | Q25: =IF(LEN(K25)>0,1,0) -> 0 | R25: =IF(LEN(L25)>0,1,0) -> 0 | S25: =IF(LEN(M25)>0,1,0) -> 0 | T25: =IF(LEN(N25)>0,1,0) -> 0 | U25: =IF(LEN(O25)>0,1,0) -> 0
A26: Changed | B26: ACTIVE | C26: Fixed Assets | E26: A436_00 | K26: =IFERROR(VLOOKUP($E26 & "|" & F26,comparison!$A$2:$A$19,1,FALSE),"") | L26: =IFERROR(VLOOKUP($E26 & "|" & G26,comparison!$A$2:$A$19,1,FALSE),"") | M26: =IFERROR(VLOOKUP($E26 & "|" & H26,comparison!$A$2:$A$19,1,FALSE),"") | N26: =IFERROR(VLOOKUP($E26 & "|" & I26,comparison!$A$2:$A$19,1,FALSE),"") | O26: =IFERROR(VLOOKUP($E26 & "|" & J26,comparison!$A$2:$A$19,1,FALSE),"") | Q26: =IF(LEN(K26)>0,1,0) -> 0 | R26: =IF(LEN(L26)>0,1,0) -> 0 | S26: =IF(LEN(M26)>0,1,0) -> 0 | T26: =IF(LEN(N26)>0,1,0) -> 0 | U26: =IF(LEN(O26)>0,1,0) -> 0
A27: Changed | B27: ACTIVE | C27: Other Intangible Assets | E27: A437_00 | K27: =IFERROR(VLOOKUP($E27 & "|" & F27,comparison!$A$2:$A$19,1,FALSE),"") | L27: =IFERROR(VLOOKUP($E27 & "|" & G27,comparison!$A$2:$A$19,1,FALSE),"") | M27: =IFERROR(VLOOKUP($E27 & "|" & H27,comparison!$A$2:$A$19,1,FALSE),"") | N27: =IFERROR(VLOOKUP($E27 & "|" & I27,comparison!$A$2:$A$19,1,FALSE),"") | O27: =IFERROR(VLOOKUP($E27 & "|" & J27,comparison!$A$2:$A$19,1,FALSE),"") | Q27: =IF(LEN(K27)>0,1,0) -> 0 | R27: =IF(LEN(L27)>0,1,0) -> 0 | S27: =IF(LEN(M27)>0,1,0) -> 0 | T27: =IF(LEN(N27)>0,1,0) -> 0 | U27: =IF(LEN(O27)>0,1,0) -> 0
A28: Changed | B28: ACTIVE | C28: Fixed Assets | E28: A450_00 | K28: =IFERROR(VLOOKUP($E28 & "|" & F28,comparison!$A$2:$A$19,1,FALSE),"") | L28: =IFERROR(VLOOKUP($E28 & "|" & G28,comparison!$A$2:$A$19,1,FALSE),"") | M28: =IFERROR(VLOOKUP($E28 & "|" & H28,comparison!$A$2:$A$19,1,FALSE),"") | N28: =IFERROR(VLOOKUP($E28 & "|" & I28,comparison!$A$2:$A$19,1,FALSE),"") | O28: =IFERROR(VLOOKUP($E28 & "|" & J28,comparison!$A$2:$A$19,1,FALSE),"") | Q28: =IF(LEN(K28)>0,1,0) -> 0 | R28: =IF(LEN(L28)>0,1,0) -> 0 | S28: =IF(LEN(M28)>0,1,0) -> 0 | T28: =IF(LEN(N28)>0,1,0) -> 0 | U28: =IF(LEN(O28)>0,1,0) -> 0
A29: Changed | B29: ACTIVE | C29: Fixed Assets | E29: A469_00 | K29: =IFERROR(VLOOKUP($E29 & "|" & F29,comparison!$A$2:$A$19,1,FALSE),"") | L29: =IFERROR(VLOOKUP($E29 & "|" & G29,comparison!$A$2:$A$19,1,FALSE),"") | M29: =IFERROR(VLOOKUP($E29 & "|" & H29,comparison!$A$2:$A$19,1,FALSE),"") | N29: =IFERROR(VLOOKUP($E29 & "|" & I29,comparison!$A$2:$A$19,1,FALSE),"") | O29: =IFERROR(VLOOKUP($E29 & "|" & J29,comparison!$A$2:$A$19,1,FALSE),"") | Q29: =IF(LEN(K29)>0,1,0) -> 0 | R29: =IF(LEN(L29)>0,1,0) -> 0 | S29: =IF(LEN(M29)>0,1,0) -> 0 | T29: =IF(LEN(N29)>0,1,0) -> 0 | U29: =IF(LEN(O29)>0,1,0) -> 0
A30: Changed | B30: ACTIVE | C30: SST only check | E30: A834_00 | I30: CON_10000 | K30: =IFERROR(VLOOKUP($E30 & "|" & F30,comparison!$A$2:$A$19,1,FALSE),"") | L30: =IFERROR(VLOOKUP($E30 & "|" & G30,comparison!$A$2:$A$19,1,FALSE),"") | M30: =IFERROR(VLOOKUP($E30 & "|" & H30,comparison!$A$2:$A$19,1,FALSE),"") | N30: =IFERROR(VLOOKUP($E30 & "|" & I30,comparison!$A$2:$A$19,1,FALSE),"") | O30: =IFERROR(VLOOKUP($E30 & "|" & J30,comparison!$A$2:$A$19,1,FALSE),"") | Q30: =IF(LEN(K30)>0,1,0) -> 0 | R30: =IF(LEN(L30)>0,1,0) -> 0 | S30: =IF(LEN(M30)>0,1,0) -> 0 | T30: =IF(LEN(N30)>0,1,0) -> 0 | U30: =IF(LEN(O30)>0,1,0) -> 0
A31: Changed | B31: ACTIVE | C31: Debt Securities - Amortized cost | E31: AE003_09 | K31: =IFERROR(VLOOKUP($E31 & "|" & F31,comparison!$A$2:$A$19,1,FALSE),"") | L31: =IFERROR(VLOOKUP($E31 & "|" & G31,comparison!$A$2:$A$19,1,FALSE),"") | M31: =IFERROR(VLOOKUP($E31 & "|" & H31,comparison!$A$2:$A$19,1,FALSE),"") | N31: =IFERROR(VLOOKUP($E31 & "|" & I31,comparison!$A$2:$A$19,1,FALSE),"") | O31: =IFERROR(VLOOKUP($E31 & "|" & J31,comparison!$A$2:$A$19,1,FALSE),"") | Q31: =IF(LEN(K31)>0,1,0) -> 0 | R31: =IF(LEN(L31)>0,1,0) -> 0 | S31: =IF(LEN(M31)>0,1,0) -> 0 | T31: =IF(LEN(N31)>0,1,0) -> 0 | U31: =IF(LEN(O31)>0,1,0) -> 0
A32: Changed | B32: ACTIVE | C32: Debt Securities - Amortized cost | E32: AE006_09 | K32: =IFERROR(VLOOKUP($E32 & "|" & F32,comparison!$A$2:$A$19,1,FALSE),"") | L32: =IFERROR(VLOOKUP($E32 & "|" & G32,comparison!$A$2:$A$19,1,FALSE),"") | M32: =IFERROR(VLOOKUP($E32 & "|" & H32,comparison!$A$2:$A$19,1,FALSE),"") | N32: =IFERROR(VLOOKUP($E32 & "|" & I32,comparison!$A$2:$A$19,1,FALSE),"") | O32: =IFERROR(VLOOKUP($E32 & "|" & J32,comparison!$A$2:$A$19,1,FALSE),"") | Q32: =IF(LEN(K32)>0,1,0) -> 0 | R32: =IF(LEN(L32)>0,1,0) -> 0 | S32: =IF(LEN(M32)>0,1,0) -> 0 | T32: =IF(LEN(N32)>0,1,0) -> 0 | U32: =IF(LEN(O32)>0,1,0) -> 0
A33: Changed | B33: ACTIVE | C33: Debt Securities - FVOCI | E33: AE010_09 | K33: =IFERROR(VLOOKUP($E33 & "|" & F33,comparison!$A$2:$A$19,1,FALSE),"") | L33: =IFERROR(VLOOKUP($E33 & "|" & G33,comparison!$A$2:$A$19,1,FALSE),"") | M33: =IFERROR(VLOOKUP($E33 & "|" & H33,comparison!$A$2:$A$19,1,FALSE),"") | N33: =IFERROR(VLOOKUP($E33 & "|" & I33,comparison!$A$2:$A$19,1,FALSE),"") | O33: =IFERROR(VLOOKUP($E33 & "|" & J33,comparison!$A$2:$A$19,1,FALSE),"") | Q33: =IF(LEN(K33)>0,1,0) -> 0 | R33: =IF(LEN(L33)>0,1,0) -> 0 | S33: =IF(LEN(M33)>0,1,0) -> 0 | T33: =IF(LEN(N33)>0,1,0) -> 0 | U33: =IF(LEN(O33)>0,1,0) -> 0
A34: Changed | B34: ACTIVE | C34: Loans and Receivables | E34: AE018_09 | K34: =IFERROR(VLOOKUP($E34 & "|" & F34,comparison!$A$2:$A$19,1,FALSE),"") | L34: =IFERROR(VLOOKUP($E34 & "|" & G34,comparison!$A$2:$A$19,1,FALSE),"") | M34: =IFERROR(VLOOKUP($E34 & "|" & H34,comparison!$A$2:$A$19,1,FALSE),"") | N34: =IFERROR(VLOOKUP($E34 & "|" & I34,comparison!$A$2:$A$19,1,FALSE),"") | O34: =IFERROR(VLOOKUP($E34 & "|" & J34,comparison!$A$2:$A$19,1,FALSE),"") | Q34: =IF(LEN(K34)>0,1,0) -> 0 | R34: =IF(LEN(L34)>0,1,0) -> 0 | S34: =IF(LEN(M34)>0,1,0) -> 0 | T34: =IF(LEN(N34)>0,1,0) -> 0 | U34: =IF(LEN(O34)>0,1,0) -> 0
A35: Changed | B35: ACTIVE | C35: Loans and Receivables | E35: AE021_09 | K35: =IFERROR(VLOOKUP($E35 & "|" & F35,comparison!$A$2:$A$19,1,FALSE),"") | L35: =IFERROR(VLOOKUP($E35 & "|" & G35,comparison!$A$2:$A$19,1,FALSE),"") | M35: =IFERROR(VLOOKUP($E35 & "|" & H35,comparison!$A$2:$A$19,1,FALSE),"") | N35: =IFERROR(VLOOKUP($E35 & "|" & I35,comparison!$A$2:$A$19,1,FALSE),"") | O35: =IFERROR(VLOOKUP($E35 & "|" & J35,comparison!$A$2:$A$19,1,FALSE),"") | Q35: =IF(LEN(K35)>0,1,0) -> 0 | R35: =IF(LEN(L35)>0,1,0) -> 0 | S35: =IF(LEN(M35)>0,1,0) -> 0 | T35: =IF(LEN(N35)>0,1,0) -> 0 | U35: =IF(LEN(O35)>0,1,0) -> 0
A36: Changed | B36: ACTIVE | C36: Equity Securities - Alternative Investments | E36: AE027_00 | K36: =IFERROR(VLOOKUP($E36 & "|" & F36,comparison!$A$2:$A$19,1,FALSE),"") | L36: =IFERROR(VLOOKUP($E36 & "|" & G36,comparison!$A$2:$A$19,1,FALSE),"") | M36: =IFERROR(VLOOKUP($E36 & "|" & H36,comparison!$A$2:$A$19,1,FALSE),"") | N36: =IFERROR(VLOOKUP($E36 & "|" & I36,comparison!$A$2:$A$19,1,FALSE),"") | O36: =IFERROR(VLOOKUP($E36 & "|" & J36,comparison!$A$2:$A$19,1,FALSE),"") | Q36: =IF(LEN(K36)>0,1,0) -> 0 | R36: =IF(LEN(L36)>0,1,0) -> 0 | S36: =IF(LEN(M36)>0,1,0) -> 0 | T36: =IF(LEN(N36)>0,1,0) -> 0 | U36: =IF(LEN(O36)>0,1,0) -> 0
A37: Changed | B37: ACTIVE | C37: Loans and Receivables | E37: AE027_09 | K37: =IFERROR(VLOOKUP($E37 & "|" & F37,comparison!$A$2:$A$19,1,FALSE),"") | L37: =IFERROR(VLOOKUP($E37 & "|" & G37,comparison!$A$2:$A$19,1,FALSE),"") | M37: =IFERROR(VLOOKUP($E37 & "|" & H37,comparison!$A$2:$A$19,1,FALSE),"") | N37: =IFERROR(VLOOKUP($E37 & "|" & I37,comparison!$A$2:$A$19,1,FALSE),"") | O37: =IFERROR(VLOOKUP($E37 & "|" & J37,comparison!$A$2:$A$19,1,FALSE),"") | Q37: =IF(LEN(K37)>0,1,0) -> 0 | R37: =IF(LEN(L37)>0,1,0) -> 0 | S37: =IF(LEN(M37)>0,1,0) -> 0 | T37: =IF(LEN(N37)>0,1,0) -> 0 | U37: =IF(LEN(O37)>0,1,0) -> 0
A38: Changed | B38: ACTIVE | C38: Loans and Receivables | E38: AE029_09 | K38: =IFERROR(VLOOKUP($E38 & "|" & F38,comparison!$A$2:$A$19,1,FALSE),"") | L38: =IFERROR(VLOOKUP($E38 & "|" & G38,comparison!$A$2:$A$19,1,FALSE),"") | M38: =IFERROR(VLOOKUP($E38 & "|" & H38,comparison!$A$2:$A$19,1,FALSE),"") | N38: =IFERROR(VLOOKUP($E38 & "|" & I38,comparison!$A$2:$A$19,1,FALSE),"") | O38: =IFERROR(VLOOKUP($E38 & "|" & J38,comparison!$A$2:$A$19,1,FALSE),"") | Q38: =IF(LEN(K38)>0,1,0) -> 0 | R38: =IF(LEN(L38)>0,1,0) -> 0 | S38: =IF(LEN(M38)>0,1,0) -> 0 | T38: =IF(LEN(N38)>0,1,0) -> 0 | U38: =IF(LEN(O38)>0,1,0) -> 0
B39: ACTIVE | C39: ZIE only | E39: AE100_70 | K39: =IFERROR(VLOOKUP($E39 & "|" & F39,comparison!$A$2:$A$19,1,FALSE),"") | L39: =IFERROR(VLOOKUP($E39 & "|" & G39,comparison!$A$2:$A$19,1,FALSE),"") | M39: =IFERROR(VLOOKUP($E39 & "|" & H39,comparison!$A$2:$A$19,1,FALSE),"") | N39: =IFERROR(VLOOKUP($E39 & "|" & I39,comparison!$A$2:$A$19,1,FALSE),"") | O39: =IFERROR(VLOOKUP($E39 & "|" & J39,comparison!$A$2:$A$19,1,FALSE),"") | Q39: =IF(LEN(K39)>0,1,0) -> 0 | R39: =IF(LEN(L39)>0,1,0) -> 0 | S39: =IF(LEN(M39)>0,1,0) -> 0 | T39: =IF(LEN(N39)>0,1,0) -> 0 | U39: =IF(LEN(O39)>0,1,0) -> 0
B40: ACTIVE | C40: ZIE only | E40: AE101_70 | K40: =IFERROR(VLOOKUP($E40 & "|" & F40,comparison!$A$2:$A$19,1,FALSE),"") | L40: =IFERROR(VLOOKUP($E40 & "|" & G40,comparison!$A$2:$A$19,1,FALSE),"") | M40: =IFERROR(VLOOKUP($E40 & "|" & H40,comparison!$A$2:$A$19,1,FALSE),"") | N40: =IFERROR(VLOOKUP($E40 & "|" & I40,comparison!$A$2:$A$19,1,FALSE),"") | O40: =IFERROR(VLOOKUP($E40 & "|" & J40,comparison!$A$2:$A$19,1,FALSE),"") | Q40: =IF(LEN(K40)>0,1,0) -> 0 | R40: =IF(LEN(L40)>0,1,0) -> 0 | S40: =IF(LEN(M40)>0,1,0) -> 0 | T40: =IF(LEN(N40)>0,1,0) -> 0 | U40: =IF(LEN(O40)>0,1,0) -> 0
...

Sheet FIP Conditions
A1: Key | B1: MethC | C1: MK | D1: Medium Text MK | E1: Normal X-Check No | F1: X-Check Medium Text | G1: UCFV20G-TRUE_BRANCH | H1: Condition No | I1: Condition Medium Text
A2: =E2 & "|" &H2 -> 3_CACC_020|3_PVLC | B2: 8 | C2: DV100 | D2: Data Entry Validation 100/IFRS | E2: 3_CACC_020 | F2: AC: Counterparty Accounts | H2: 3_PVLC | I2: Amount LC = 0 / Quanity = 0
A3: =E3 & "|" &H3 -> 3_CACC_030|3_PVLC | B3: 8 | C3: DV100 | D3: Data Entry Validation 100/IFRS | E3: 3_CACC_030 | F3: AC: Plan-Accounts | H3: 3_PVLC | I3: Amount LC = 0 / Quanity = 0
A4: =E4 & "|" &H4 -> 3_CACC_050|3_PVLC | B4: 8 | C4: DV100 | D4: Data Entry Validation 100/IFRS | E4: 3_CACC_050 | F4: Account, where only quantities postable | H4: 3_PVLC | I4: Amount LC = 0 / Quanity = 0
A5: =E5 & "|" &H5 -> 3_CACC_130|3_ZTOM_000 | B5: 8 | C5: DV100 | D5: Data Entry Validation 100/IFRS | E5: 3_CACC_130 | F5: IFRS ToM: not relevant accounts | H5: 3_ZTOM_000 | I5: Breakdown Check ToM: relevance
A6: =E6 & "|" &H6 -> 3_CACC_I10|3_ZPRU_000 | B6: 8 | C6: DV100 | D6: Data Entry Validation 100/IFRS | E6: 3_CACC_I10 | F6: IFRS PRU: not relevant Accounts | H6: 3_ZPRU_000 | I6: Breakdown check PRU: relevance
A7: =E7 & "|" &H7 -> 3_CACC_I20|3_ZPSE_000 | B7: 8 | C7: DV100 | D7: Data Entry Validation 100/IFRS | E7: 3_CACC_I20 | F7: IFRS PSE: not relevant accounts | H7: 3_ZPSE_000 | I7: Breakdown check PSE: relevance
A8: =E8 & "|" &H8 -> 3_CACC_I40|3_ZALC_000 | B8: 8 | C8: DV100 | D8: Data Entry Validation 100/IFRS | E8: 3_CACC_I40 | F8: IFRS ALC not relevant Accounts | H8: 3_ZALC_000 | I8: Breakdown Check ALC: relevance
A9: =E9 & "|" &H9 -> 3_CACC_I50|3_ZGRC_000 | B9: 8 | C9: DV100 | D9: Data Entry Validation 100/IFRS | E9: 3_CACC_I50 | F9: IFRS Gross / Ceded not relevant Accounts | H9: 3_ZGRC_000 | I9: Breakdown Check GRC: relevance
A10: =E10 & "|" &H10 -> 3_CACC_I60|3_ZMAT_000 | B10: 8 | C10: DV100 | D10: Data Entry Validation 100/IFRS | E10: 3_CACC_I60 | F10: IFRS MAT not relevant Accounts | H10: 3_ZMAT_000 | I10: Breakdown Check MAT: relevance
A11: =E11 & "|" &H11 -> 3_CACC_I70|3_ZREX_000 | B11: 8 | C11: DV100 | D11: Data Entry Validation 100/IFRS | E11: 3_CACC_I70 | F11: IFRS REX relevant Accounts | H11: 3_ZREX_000 | I11: BD Check REX: relevance
A12: =E12 & "|" &H12 -> 3_CACC_I80|3_ZVLT_000 | B12: 8 | C12: DV100 | D12: Data Entry Validation 100/IFRS | E12: 3_CACC_I80 | F12: IFRS VAL not relevant Accounts | H12: 3_ZVLT_000 | I12: BD Check VAL: relevance
A13: =E13 & "|" &H13 -> 3_CACC_I90|3_ZVAR_000 | B13: 8 | C13: DV100 | D13: Data Entry Validation 100/IFRS | E13: 3_CACC_I90 | F13: IFRS VAR not relevant Accounts | H13: 3_ZVAR_000 | I13: BD Check VAR: relevance
... A16: =E16 & "|" &H16 -> 3_CACY_NA|3_CACC_IB0 | B16: 8 | C16: DV100 | D16: Data Entry Validation 100/IFRS | E16: 3_CACY_NA | F16: AY = not assigned | H16: 3_CACC_IB0 | I16: IFRS ACY not relevant Accounts
A17: =E17 & "|" &H17 -> 3_CACY_RV|3_CACC_IB0 | B17: 8 | C17: DV100 | D17: Data Entry Validation 100/IFRS | E17: 3_CACY_RV | F17: ACY with real value | G17: X | H17: 3_CACC_IB0 | I17: IFRS ACY not relevant Accounts
A18: =E18 & "|" &H18 -> 3_CALC_NA|3_CACC_I40 | B18: 8 | C18: DV100 | D18: Data Entry Validation 100/IFRS | E18: 3_CALC_NA | F18: ALC = not assigned | H18: 3_CACC_I40 | I18: IFRS ALC not relevant Accounts
A19: =E19 & "|" &H19 -> 3_CALC_RV|3_CACC_I40 | B19: 8 | C19: DV100 | D19: Data Entry Validation 100/IFRS | E19: 3_CALC_RV | F19: ALC with real value | G19: X | H19: 3_CACC_I40 | I19: IFRS ALC not relevant Accounts
A20: =E20 & "|" &H20 -> 3_CAMT_000|3_CACC_050 | B20: 8 | C20: DV100 | D20: Data Entry Validation 100/IFRS | E20: 3_CAMT_000 | F20: Amount LC posted? | G20: X | H20: 3_CACC_050 | I20: Account, where only quantities postable
A21: =E21 & "|" &H21 -> 3_CGRC_NA|3_CACC_I50 | B21: 8 | C21: DV100 | D21: Data Entry Validation 100/IFRS | E21: 3_CGRC_NA | F21: GRC = not assigned | H21: 3_CACC_I50 | I21: IFRS Gross / Ceded not relevant Accounts
A22: =E22 & "|" &H22 -> 3_CGRC_RV|3_CACC_I50 | B22: 8 | C22: DV100 | D22: Data Entry Validation 100/IFRS | E22: 3_CGRC_RV | F22: GRC with real value | G22: X | H22: 3_CACC_I50 | I22: IFRS Gross / Ceded not relevant Accounts
A23: =E23 & "|" &H23 -> 3_CISG_010|3_PVLC | B23: 8 | C23: DV100 | D23: Data Entry Validation 100/IFRS | E23: 3_CISG_010 | F23: Investee Segment: only X allowed | H23: 3_PVLC | I23: Amount LC = 0 / Quanity = 0
A24: =E24 & "|" &H24 -> 3_CLOB_NA|3_CACC_IA0 | B24: 8 | C24: DV100 | D24: Data Entry Validation 100/IFRS | E24: 3_CLOB_NA | F24: Line of Business = not assigned | H24: 3_CACC_IA0 | I24: IFRS LOB not relevant Accounts
A25: =E25 & "|" &H25 -> 3_CLOB_RV|3_CACC_IA0 | B25: 8 | C25: DV100 | D25: Data Entry Validation 100/IFRS | E25: 3_CLOB_RV | F25: Line of Business with real value | G25: X | H25: 3_CACC_IA0 | I25: IFRS LOB not relevant Accounts
A26: =E26 & "|" &H26 -> 3_CMAT_NA|3_CACC_I60 | B26: 8 | C26: DV100 | D26: Data Entry Validation 100/IFRS | E26: 3_CMAT_NA | F26: MAT = not assigned | H26: 3_CACC_I60 | I26: IFRS MAT not relevant Accounts
A27: =E27 & "|" &H27 -> 3_CMAT_RV|3_CACC_I60 | B27: 8 | C27: DV100 | D27: Data Entry Validation 100/IFRS | E27: 3_CMAT_RV | F27: MAT with real value | G27: X | H27: 3_CACC_I60 | I27: IFRS MAT not relevant Accounts
A28: =E28 & "|" &H28 -> 3_CPRU_NA|3_CACC_I10 | B28: 8 | C28: DV100 | D28: Data Entry Validation 100/IFRS | E28: 3_CPRU_NA | F28: PRU = not assigned | H28: 3_CACC_I10 | I28: IFRS PRU: not relevant Accounts
A29: =E29 & "|" &H29 -> 3_CPRU_NAY|3_CPRU_RU | B29: 8 | C29: DV100 | D29: Data Entry Validation 100/IFRS | E29: 3_CPRU_NAY | F29: PRU = not assigned, account 29102 | G29: X | H29: 3_CPRU_RU | I29: PRU = RU
A30: =E30 & "|" &H30 -> 3_CPRU_RU|3_CPRU_NA | B30: 8 | C30: DV100 | D30: Data Entry Validation 100/IFRS | E30: 3_CPRU_RU | F30: PRU = RU | H30: 3_CPRU_NA | I30: PRU = not assigned
A31: =E31 & "|" &H31 -> 3_CPRU_RV|3_CACC_I10 | B31: 8 | C31: DV100 | D31: Data Entry Validation 100/IFRS | E31: 3_CPRU_RV | F31: PRU with real value | G31: X | H31: 3_CACC_I10 | I31: IFRS PRU: not relevant Accounts
A32: =E32 & "|" &H32 -> 3_CPSE_NA|3_CACC_I20 | B32: 8 | C32: DV100 | D32: Data Entry Validation 100/IFRS | E32: 3_CPSE_NA | F32: PSE = not assigned | H32: 3_CACC_I20 | I32: IFRS PSE: not relevant accounts
A33: =E33 & "|" &H33 -> 3_CPSE_RV|3_CACC_I20 | B33: 8 | C33: DV100 | D33: Data Entry Validation 100/IFRS | E33: 3_CPSE_RV | F33: PSE with real value | G33: X | H33: 3_CACC_I20 | I33: IFRS PSE: not relevant accounts
A34: =E34 & "|" &H34 -> 3_CQTY_000|3_CACC_050 | B34: 8 | C34: DV100 | D34: Data Entry Validation 100/IFRS | E34: 3_CQTY_000 | F34: Quantity posted? | H34: 3_CACC_050 | I34: Account, where only quantities postable
A35: =E35 & "|" &H35 -> 3_CREX_NA|3_CACC_I70 | B35: 8 | C35: DV100 | D35: Data Entry Validation 100/IFRS | E35: 3_CREX_NA | F35: REX = not assigned | H35: 3_CACC_I70 | I35: IFRS REX relevant Accounts
A36: =E36 & "|" &H36 -> 3_CREX_RV|3_CACC_I70 | B36: 8 | C36: DV100 | D36: Data Entry Validation 100/IFRS | E36: 3_CREX_RV | F36: REX with real value | G36: X | H36: 3_CACC_I70 | I36: IFRS REX relevant Accounts
A37: =E37 & "|" &H37 -> 3_CTOM_NA|3_CACC_130 | B37: 8 | C37: DV100 | D37: Data Entry Validation 100/IFRS | E37: 3_CTOM_NA | F37: TOM = not assigned | H37: 3_CACC_130 | I37: IFRS ToM: not relevant accounts
A38: =E38 & "|" &H38 -> 3_CTOM_RV|3_CACC_130 | B38: 8 | C38: DV100 | D38: Data Entry Validation 100/IFRS | E38: 3_CTOM_RV | F38: TOM with real value | G38: X | H38: 3_CACC_130 | I38: IFRS ToM: not relevant accounts
A39: =E39 & "|" &H39 -> 3_CVAR_NA|3_CACC_I90 | B39: 8 | C39: DV100 | D39: Data Entry Validation 100/IFRS | E39: 3_CVAR_NA | F39: VAR = not assigned | H39: 3_CACC_I90 | I39: IFRS VAR not relevant Accounts
A40: =E40 & "|" &H40 -> 3_CVAR_RV|3_CACC_I90 | B40: 8 | C40: DV100 | D40: Data Entry Validation 100/IFRS | E40: 3_CVAR_RV | F40: VAR with real value | G40: X | H40: 3_CACC_I90 | I40: IFRS VAR not relevant Accounts
A41: =E41 & "|" &H41 -> 3_CVLT_NA|3_CACC_I80 | B41: 8 | C41: DV100 | D41: Data Entry Validation 100/IFRS | E41: 3_CVLT_NA | F41: VAL = not assigned | H41: 3_CACC_I80 | I41: IFRS VAL not relevant Accounts
A42: =E42 & "|" &H42 -> 3_CVLT_RV|3_CACC_I80 | B42: 8 | C42: DV100 | D42: Data Entry Validation 100/IFRS | E42: 3_CVLT_RV | F42: VAL with real value | G42: X | H42: 3_CACC_I80 | I42: IFRS VAL not relevant Accounts
...

Sheet Sheet1
A2: Type of change | B2: Status | C2: Category | D2: Sense Check | E2: X-Check No. | F2: Reference X-Check (Condition) | G2: Applicable Quarters | H2: Included RUs | I2: Excluded RUs | J2: Reference X-Check (Limit, %) | L2: Reference X-Check (Condition) | M2: Applicable Quarters | N2: Included RUs | O2: Excluded RUs | P2: Reference X-Check (Limit, %)
A3: Changed | B3: ACTIVE | C3: Real Estate held for Investment | E3: A047_00 | L3: =IF(F3="","",$E3 & "|" & F3) | M3: =IF(G3="","",$E3 & "|" & G3) | N3: =IF(H3="","",$E3 & "|" & H3) | O3: =IF(I3="","",$E3 & "|" & I3) | P3: =IF(J3="","",$E3 & "|" & J3)
A4: Changed | B4: ACTIVE | C4: Real Estate held for Investment | E4: A047_00 | L4: =IF(F4="","",$E4 & "|" & F4) | M4: =IF(G4="","",$E4 & "|" & G4) | N4: =IF(H4="","",$E4 & "|" & H4) | O4: =IF(I4="","",$E4 & "|" & I4) | P4: =IF(J4="","",$E4 & "|" & J4)
A5: Changed | B5: ACTIVE | C5: Real Estate held for Investment | E5: A047_00 | L5: =IF(F5="","",$E5 & "|" & F5) | M5: =IF(G5="","",$E5 & "|" & G5) | N5: =IF(H5="","",$E5 & "|" & H5) | O5: =IF(I5="","",$E5 & "|" & I5) | P5: =IF(J5="","",$E5 & "|" & J5)
A6: Changed | B6: ACTIVE | C6: Equity Securities - Common Stock | D6: yes | E6: A074_00 | L6: =IF(F6="","",$E6 & "|" & F6) | M6: =IF(G6="","",$E6 & "|" & G6) | N6: =IF(H6="","",$E6 & "|" & H6) | O6: =IF(I6="","",$E6 & "|" & I6) | P6: =IF(J6="","",$E6 & "|" & J6)
A7: Changed | B7: ACTIVE | C7: Equity Securities - Common Stock | D7: yes | E7: A074_00 | L7: =IF(F7="","",$E7 & "|" & F7) | M7: =IF(G7="","",$E7 & "|" & G7) | N7: =IF(H7="","",$E7 & "|" & H7) | O7: =IF(I7="","",$E7 & "|" & I7) | P7: =IF(J7="","",$E7 & "|" & J7)
A8: Changed | B8: ACTIVE | C8: Equity Securities - Common Stock | D8: yes | E8: A074_00 | L8: =IF(F8="","",$E8 & "|" & F8) | M8: =IF(G8="","",$E8 & "|" & G8) | N8: =IF(H8="","",$E8 & "|" & H8) | O8: =IF(I8="","",$E8 & "|" & I8) | P8: =IF(J8="","",$E8 & "|" & J8)
A9: Changed | B9: ACTIVE | C9: Equity Securities - Common Stock | D9: yes | E9: A074_00 | L9: =IF(F9="","",$E9 & "|" & F9) | M9: =IF(G9="","",$E9 & "|" & G9) | N9: =IF(H9="","",$E9 & "|" & H9) | O9: =IF(I9="","",$E9 & "|" & I9) | P9: =IF(J9="","",$E9 & "|" & J9)
A10: Changed | B10: ACTIVE | C10: Equity Securities - Common Stock | D10: yes | E10: A074_00 | L10: =IF(F10="","",$E10 & "|" & F10) | M10: =IF(G10="","",$E10 & "|" & G10) | N10: =IF(H10="","",$E10 & "|" & H10) | O10: =IF(I10="","",$E10 & "|" & I10) | P10: =IF(J10="","",$E10 & "|" & J10)
A11: Changed | B11: ACTIVE | C11: Equity Securities - Common Stock | D11: yes | E11: A074_00 | L11: =IF(F11="","",$E11 & "|" & F11) | M11: =IF(G11="","",$E11 & "|" & G11) | N11: =IF(H11="","",$E11 & "|" & H11) | O11: =IF(I11="","",$E11 & "|" & I11) | P11: =IF(J11="","",$E11 & "|" & J11)
A12: Changed | B12: ACTIVE | C12: Equity Securities - Common Stock | D12: yes | E12: A074_00 | L12: =IF(F12="","",$E12 & "|" & F12) | M12: =IF(G12="","",$E12 & "|" & G12) | N12: =IF(H12="","",$E12 & "|" & H12) | O12: =IF(I12="","",$E12 & "|" & I12) | P12: =IF(J12="","",$E12 & "|" & J12)
A13: Changed | B13: ACTIVE | C13: Equity Securities - Common Stock | D13: yes | E13: A074_00 | L13: =IF(F13="","",$E13 & "|" & F13) | M13: =IF(G13="","",$E13 & "|" & G13) | N13: =IF(H13="","",$E13 & "|" & H13) | O13: =IF(I13="","",$E13 & "|" & I13) | P13: =IF(J13="","",$E13 & "|" & J13)
A14: Changed | B14: ACTIVE | C14: Equity Securities - Common Stock | E14: A079_00 | L14: =IF(F14="","",$E14 & "|" & F14) | M14: =IF(G14="","",$E14 & "|" & G14) | N14: =IF(H14="","",$E14 & "|" & H14) | O14: =IF(I14="","",$E14 & "|" & I14) | P14: =IF(J14="","",$E14 & "|" & J14)
A15: Changed | B15: ACTIVE | C15: Equity Securities - Common Stock | E15: A079_00 | L15: =IF(F15="","",$E15 & "|" & F15) | M15: =IF(G15="","",$E15 & "|" & G15) | N15: =IF(H15="","",$E15 & "|" & H15) | O15: =IF(I15="","",$E15 & "|" & I15) | P15: =IF(J15="","",$E15 & "|" & J15)
A16: Changed | B16: ACTIVE | C16: Equity Securities - Common Stock | E16: A079_00 | L16: =IF(F16="","",$E16 & "|" & F16) | M16: =IF(G16="","",$E16 & "|" & G16) | N16: =IF(H16="","",$E16 & "|" & H16) | O16: =IF(I16="","",$E16 & "|" & I16) | P16: =IF(J16="","",$E16 & "|" & J16)
A17: Changed | B17: ACTIVE | C17: Equity Securities - Common Stock | E17: A079_00 | L17: =IF(F17="","",$E17 & "|" & F17) | M17: =IF(G17="","",$E17 & "|" & G17) | N17: =IF(H17="","",$E17 & "|" & H17) | O17: =IF(I17="","",$E17 & "|" & I17) | P17: =IF(J17="","",$E17 & "|" & J17)
A18: Changed | B18: ACTIVE | C18: Equity Securities - Common Stock | E18: A079_00 | L18: =IF(F18="","",$E18 & "|" & F18) | M18: =IF(G18="","",$E18 & "|" & G18) | N18: =IF(H18="","",$E18 & "|" & H18) | O18: =IF(I18="","",$E18 & "|" & I18) | P18: =IF(J18="","",$E18 & "|" & J18)
A19: Changed | B19: ACTIVE | C19: Equity Securities - Common Stock | E19: A079_00 | L19: =IF(F19="","",$E19 & "|" & F19) | M19: =IF(G19="","",$E19 & "|" & G19) | N19: =IF(H19="","",$E19 & "|" & H19) | O19: =IF(I19="","",$E19 & "|" & I19) | P19: =IF(J19="","",$E19 & "|" & J19)
A20: Changed | B20: ACTIVE | C20: Equity Securities - Common Stock | E20: A079_00 | L20: =IF(F20="","",$E20 & "|" & F20) | M20: =IF(G20="","",$E20 & "|" & G20) | N20: =IF(H20="","",$E20 & "|" & H20) | O20: =IF(I20="","",$E20 & "|" & I20) | P20: =IF(J20="","",$E20 & "|" & J20)
A21: Changed | B21: ACTIVE | C21: Equity Securities - Common Stock | E21: A079_00 | L21: =IF(F21="","",$E21 & "|" & F21) | M21: =IF(G21="","",$E21 & "|" & G21) | N21: =IF(H21="","",$E21 & "|" & H21) | O21: =IF(I21="","",$E21 & "|" & I21) | P21: =IF(J21="","",$E21 & "|" & J21)
A22: Changed | B22: ACTIVE | C22: Equity Securities - Common Stock | E22: A079_00 | L22: =IF(F22="","",$E22 & "|" & F22) | M22: =IF(G22="","",$E22 & "|" & G22) | N22: =IF(H22="","",$E22 & "|" & H22) | O22: =IF(I22="","",$E22 & "|" & I22) | P22: =IF(J22="","",$E22 & "|" & J22)
A23: Changed | B23: ACTIVE | C23: Equity Securities - Common Stock | E23: A079_00 | L23: =IF(F23="","",$E23 & "|" & F23) | M23: =IF(G23="","",$E23 & "|" & G23) | N23: =IF(H23="","",$E23 & "|" & H23) | O23: =IF(I23="","",$E23 & "|" & I23) | P23: =IF(J23="","",$E23 & "|" & J23)
A24: Changed | B24: ACTIVE | C24: Equity Securities - Common Stock | E24: A079_00 | L24: =IF(F24="","",$E24 & "|" & F24) | M24: =IF(G24="","",$E24 & "|" & G24) | N24: =IF(H24="","",$E24 & "|" & H24) | O24: =IF(I24="","",$E24 & "|" & I24) | P24: =IF(J24="","",$E24 & "|" & J24)
A25: Changed | B25: ACTIVE | C25: Equity Securities - Common Stock | E25: A079_00 | L25: =IF(F25="","",$E25 & "|" & F25) | M25: =IF(G25="","",$E25 & "|" & G25) | N25: =IF(H25="","",$E25 & "|" & H25) | O25: =IF(I25="","",$E25 & "|" & I25) | P25: =IF(J25="","",$E25 & "|" & J25)
... A89: Changed | B89: ACTIVE | C89: Equity Securities - Common Stock | E89: A081_00 | L89: =IF(F89="","",$E89 & "|" & F89) | M89: =IF(G89="","",$E89 & "|" & G89) | N89: =IF(H89="","",$E89 & "|" & H89) | O89: =IF(I89="","",$E89 & "|" & I89) | P89: =IF(J89="","",$E89 & "|" & J89)
A90: Changed | B90: ACTIVE | C90: Equity Securities - Common Stock | D90: yes | E90: A082_00 | L90: =IF(F90="","",$E90 & "|" & F90) | M90: =IF(G90="","",$E90 & "|" & G90) | N90: =IF(H90="","",$E90 & "|" & H90) | O90: =IF(I90="","",$E90 & "|" & I90) | P90: =IF(J90="","",$E90 & "|" & J90)
A91: Changed | B91: ACTIVE | C91: Equity Securities - Common Stock | D91: yes | E91: A082_00 | L91: =IF(F91="","",$E91 & "|" & F91) | M91: =IF(G91="","",$E91 & "|" & G91) | N91: =IF(H91="","",$E91 & "|" & H91) | O91: =IF(I91="","",$E91 & "|" & I91) | P91: =IF(J91="","",$E91 & "|" & J91)
A92: Changed | B92: ACTIVE | C92: Equity Securities - Common Stock | D92: yes | E92: A082_00 | L92: =IF(F92="","",$E92 & "|" & F92) | M92: =IF(G92="","",$E92 & "|" & G92) | N92: =IF(H92="","",$E92 & "|" & H92) | O92: =IF(I92="","",$E92 & "|" & I92) | P92: =IF(J92="","",$E92 & "|" & J92)
A93: Changed | B93: ACTIVE | C93: Equity Securities - Common Stock | D93: yes | E93: A082_00 | L93: =IF(F93="","",$E93 & "|" & F93) | M93: =IF(G93="","",$E93 & "|" & G93) | N93: =IF(H93="","",$E93 & "|" & H93) | O93: =IF(I93="","",$E93 & "|" & I93) | P93: =IF(J93="","",$E93 & "|" & J93)
A94: Changed | B94: ACTIVE | C94: Equity Securities - Common Stock | D94: yes | E94: A082_00 | L94: =IF(F94="","",$E94 & "|" & F94) | M94: =IF(G94="","",$E94 & "|" & G94) | N94: =IF(H94="","",$E94 & "|" & H94) | O94: =IF(I94="","",$E94 & "|" & I94) | P94: =IF(J94="","",$E94 & "|" & J94)
A95: Changed | B95: ACTIVE | C95: Equity Securities - Common Stock | D95: yes | E95: A082_00 | L95: =IF(F95="","",$E95 & "|" & F95) | M95: =IF(G95="","",$E95 & "|" & G95) | N95: =IF(H95="","",$E95 & "|" & H95) | O95: =IF(I95="","",$E95 & "|" & I95) | P95: =IF(J95="","",$E95 & "|" & J95)
A96: Changed | B96: ACTIVE | C96: Equity Securities - Common Stock | D96: yes | E96: A082_00 | L96: =IF(F96="","",$E96 & "|" & F96) | M96: =IF(G96="","",$E96 & "|" & G96) | N96: =IF(H96="","",$E96 & "|" & H96) | O96: =IF(I96="","",$E96 & "|" & I96) | P96: =IF(J96="","",$E96 & "|" & J96)
A97: Changed | B97: ACTIVE | C97: Equity Securities - Common Stock | D97: yes | E97: A082_00 | L97: =IF(F97="","",$E97 & "|" & F97) | M97: =IF(G97="","",$E97 & "|" & G97) | N97: =IF(H97="","",$E97 & "|" & H97) | O97: =IF(I97="","",$E97 & "|" & I97) | P97: =IF(J97="","",$E97 & "|" & J97)
A98: Changed | B98: ACTIVE | C98: Equity Securities - Common Stock | D98: yes | E98: A082_00 | L98: =IF(F98="","",$E98 & "|" & F98) | M98: =IF(G98="","",$E98 & "|" & G98) | N98: =IF(H98="","",$E98 & "|" & H98) | O98: =IF(I98="","",$E98 & "|" & I98) | P98: =IF(J98="","",$E98 & "|" & J98)
A99: Changed | B99: ACTIVE | C99: Equity Securities - Common Stock | D99: yes | E99: A082_00 | L99: =IF(F99="","",$E99 & "|" & F99) | M99: =IF(G99="","",$E99 & "|" & G99) | N99: =IF(H99="","",$E99 & "|" & H99) | O99: =IF(I99="","",$E99 & "|" & I99) | P99: =IF(J99="","",$E99 & "|" & J99)
A100: Changed | B100: ACTIVE | C100: Equity Securities - Common Stock | D100: yes | E100: A082_00 | L100: =IF(F100="","",$E100 & "|" & F100) | M100: =IF(G100="","",$E100 & "|" & G100) | N100: =IF(H100="","",$E100 & "|" & H100) | O100: =IF(I100="","",$E100 & "|" & I100) | P100: =IF(J100="","",$E100 & "|" & J100)
A101: Changed | B101: ACTIVE | C101: Equity Securities - Common Stock | D101: yes | E101: A082_00 | L101: =IF(F101="","",$E101 & "|" & F101) | M101: =IF(G101="","",$E101 & "|" & G101) | N101: =IF(H101="","",$E101 & "|" & H101) | O101: =IF(I101="","",$E101 & "|" & I101) | P101: =IF(J101="","",$E101 & "|" & J101)
... A127: Changed | B127: ACTIVE | C127: Equity Securities - Common Stock | D127: yes | E127: A082_00 | L127: =IF(F127="","",$E127 & "|" & F127) | M127: =IF(G127="","",$E127 & "|" & G127) | N127: =IF(H127="","",$E127 & "|" & H127) | O127: =IF(I127="","",$E127 & "|" & I127) | P127: =IF(J127="","",$E127 & "|" & J127)
A128: Changed | B128: ACTIVE | C128: Equity Securities - Open-end investment funds | E128: A090_00 | L128: =IF(F128="","",$E128 & "|" & F128) | M128: =IF(G128="","",$E128 & "|" & G128) | N128: =IF(H128="","",$E128 & "|" & H128) | O128: =IF(I128="","",$E128 & "|" & I128) | P128: =IF(J128="","",$E128 & "|" & J128)
A129: Changed | B129: ACTIVE | C129: Equity Securities - Open-end investment funds | E129: A090_00 | L129: =IF(F129="","",$E129 & "|" & F129) | M129: =IF(G129="","",$E129 & "|" & G129) | N129: =IF(H129="","",$E129 & "|" & H129) | O129: =IF(I129="","",$E129 & "|" & I129) | P129: =IF(J129="","",$E129 & "|" & J129)
...

Sheet cross checks all yellow
A2: Type of change | B2: Status | C2: Category | D2: Sense Check | E2: X-Check No. | F2: Reference X-Check (Condition) | G2: Applicable Quarters | H2: Included RUs | I2: Excluded RUs | J2: Reference X-Check (Limit, %) | L2: Reference X-Check (Condition) | M2: Applicable Quarters | N2: Included RUs | O2: Excluded RUs | P2: Reference X-Check (Limit, %)
A3: New xcheck or association | B3: ACTIVE | C3: FINMA statistical information | E3: SR051_00 | G3: CON_Q2_Q4 | L3: =IF(F3="","",$E3 & "|" & F3) | M3: =IF(G3="","",$E3 & "|" & G3) -> SR051_00|CON_Q2_Q4 | N3: =IF(H3="","",$E3 & "|" & H3) | O3: =IF(I3="","",$E3 & "|" & I3) | P3: =IF(J3="","",$E3 & "|" & J3)
A4: New xcheck or association | B4: ACTIVE | C4: FINMA statistical information | D4: yes | E4: SR116_00 | G4: CON_Q2_Q4 | L4: =IF(F4="","",$E4 & "|" & F4) | M4: =IF(G4="","",$E4 & "|" & G4) -> SR116_00|CON_Q2_Q4 | N4: =IF(H4="","",$E4 & "|" & H4) | O4: =IF(I4="","",$E4 & "|" & I4) | P4: =IF(J4="","",$E4 & "|" & J4)
A5: New xcheck or association | B5: ACTIVE | C5: FINMA statistical information | D5: yes | E5: SR117_00 | G5: CON_Q2_Q4 | L5: =IF(F5="","",$E5 & "|" & F5) | M5: =IF(G5="","",$E5 & "|" & G5) -> SR117_00|CON_Q2_Q4 | N5: =IF(H5="","",$E5 & "|" & H5) | O5: =IF(I5="","",$E5 & "|" & I5) | P5: =IF(J5="","",$E5 & "|" & J5)
A6: Changed | B6: ACTIVE | C6: IFRS 17 - BBA LRC CSM | E6: AS004_17 | G6: CON_Q3_Q4 | L6: =IF(F6="","",$E6 & "|" & F6) | M6: =IF(G6="","",$E6 & "|" & G6) -> AS004_17|CON_Q3_Q4 | N6: =IF(H6="","",$E6 & "|" & H6) | O6: =IF(I6="","",$E6 & "|" & I6) | P6: =IF(J6="","",$E6 & "|" & J6)
A7: Changed | B7: ACTIVE | C7: IFRS 13 - level 1,2,3 | E7: AS133_00 | G7: CON_Q4 | L7: =IF(F7="","",$E7 & "|" & F7) | M7: =IF(G7="","",$E7 & "|" & G7) -> AS133_00|CON_Q4 | N7: =IF(H7="","",$E7 & "|" & H7) | O7: =IF(I7="","",$E7 & "|" & I7) | P7: =IF(J7="","",$E7 & "|" & J7)
A8: Changed | B8: ACTIVE | C8: IFRS 13 - level 1,2,3 | E8: AS137_00 | G8: CON_Q4 | L8: =IF(F8="","",$E8 & "|" & F8) | M8: =IF(G8="","",$E8 & "|" & G8) -> AS137_00|CON_Q4 | N8: =IF(H8="","",$E8 & "|" & H8) | O8: =IF(I8="","",$E8 & "|" & I8) | P8: =IF(J8="","",$E8 & "|" & J8)
A9: Changed | B9: ACTIVE | C9: IFRS 13 - level 1,2,3 | E9: AS139_00 | G9: CON_Q4 | L9: =IF(F9="","",$E9 & "|" & F9) | M9: =IF(G9="","",$E9 & "|" & G9) -> AS139_00|CON_Q4 | N9: =IF(H9="","",$E9 & "|" & H9) | O9: =IF(I9="","",$E9 & "|" & I9) | P9: =IF(J9="","",$E9 & "|" & J9)
A10: Changed | B10: ACTIVE | C10: IFRS 13 - level 1,2,3 | E10: AS142_00 | G10: CON_Q4 | L10: =IF(F10="","",$E10 & "|" & F10) | M10: =IF(G10="","",$E10 & "|" & G10) -> AS142_00|CON_Q4 | N10: =IF(H10="","",$E10 & "|" & H10) | O10: =IF(I10="","",$E10 & "|" & I10) | P10: =IF(J10="","",$E10 & "|" & J10)
A11: Changed | B11: ACTIVE | C11: IFRS 13 - level 1,2,3 | E11: AS168_00 | G11: CON_Q4 | L11: =IF(F11="","",$E11 & "|" & F11) | M11: =IF(G11="","",$E11 & "|" & G11) -> AS168_00|CON_Q4 | N11: =IF(H11="","",$E11 & "|" & H11) | O11: =IF(I11="","",$E11 & "|" & I11) | P11: =IF(J11="","",$E11 & "|" & J11)
A12: Changed | B12: ACTIVE | C12: IFRS 17 - BBA LRC CSM | E12: LS013_17 | G12: CON_Q3_Q4 | L12: =IF(F12="","",$E12 & "|" & F12) | M12: =IF(G12="","",$E12 & "|" & G12) -> LS013_17|CON_Q3_Q4 | N12: =IF(H12="","",$E12 & "|" & H12) | O12: =IF(I12="","",$E12 & "|" & I12) | P12: =IF(J12="","",$E12 & "|" & J12)
A13: Changed | B13: ACTIVE | C13: IFRS 13 - level 1,2,3 | E13: LS142_00 | G13: CON_Q4 | L13: =IF(F13="","",$E13 & "|" & F13) | M13: =IF(G13="","",$E13 & "|" & G13) -> LS142_00|CON_Q4 | N13: =IF(H13="","",$E13 & "|" & H13) | O13: =IF(I13="","",$E13 & "|" & I13) | P13: =IF(J13="","",$E13 & "|" & J13)
A14: Changed | B14: ACTIVE | C14: IFRS 13 - level 1,2,3 | E14: S281_00 | G14: CON_Q4 | L14: =IF(F14="","",$E14 & "|" & F14) | M14: =IF(G14="","",$E14 & "|" & G14) -> S281_00|CON_Q4 | N14: =IF(H14="","",$E14 & "|" & H14) | O14: =IF(I14="","",$E14 & "|" & I14) | P14: =IF(J14="","",$E14 & "|" & J14)
A15: Changed | B15: ACTIVE | C15: IFRS 13 - level 1,2,3 | E15: S285_00 | G15: CON_Q4 | L15: =IF(F15="","",$E15 & "|" & F15) | M15: =IF(G15="","",$E15 & "|" & G15) -> S285_00|CON_Q4 | N15: =IF(H15="","",$E15 & "|" & H15) | O15: =IF(I15="","",$E15 & "|" & I15) | P15: =IF(J15="","",$E15 & "|" & J15)
A16: Changed | B16: ACTIVE | C16: IFRS 13 - level 1,2,3 | E16: S287_00 | G16: CON_Q4 | L16: =IF(F16="","",$E16 & "|" & F16) | M16: =IF(G16="","",$E16 & "|" & G16) -> S287_00|CON_Q4 | N16: =IF(H16="","",$E16 & "|" & H16) | O16: =IF(I16="","",$E16 & "|" & I16) | P16: =IF(J16="","",$E16 & "|" & J16)
A17: Changed | B17: ACTIVE | C17: IFRS 13 - level 1,2,3 | E17: S289_00 | G17: CON_Q4 | L17: =IF(F17="","",$E17 & "|" & F17) | M17: =IF(G17="","",$E17 & "|" & G17) -> S289_00|CON_Q4 | N17: =IF(H17="","",$E17 & "|" & H17) | O17: =IF(I17="","",$E17 & "|" & I17) | P17: =IF(J17="","",$E17 & "|" & J17)
... A20: Changed | B20: ACTIVE | C20: IFRS 13 - level 1,2,3 | E20: S463_00 | G20: CON_Q4 | L20: =IF(F20="","",$E20 & "|" & F20) | M20: =IF(G20="","",$E20 & "|" & G20) -> S463_00|CON_Q4 | N20: =IF(H20="","",$E20 & "|" & H20) | O20: =IF(I20="","",$E20 & "|" & I20) | P20: =IF(J20="","",$E20 & "|" & J20)

Sheet comparison
A1: EBX Data | B1: FIP Data | C1: Comparison
A2: SR051_00|CON_Q2_Q4 | B2: =VLOOKUP(A2,'FIP Conditions'!$A:$A,1,FALSE) -> SR051_00|CON_Q2_Q4 | C2: =A2=B2 -> TRUE
A3: SR116_00|CON_Q2_Q4 | B3: =VLOOKUP(A3,'FIP Conditions'!$A:$A,1,FALSE) -> SR116_00|CON_Q2_Q4 | C3: =A3=B3 -> TRUE
A4: SR117_00|CON_Q2_Q4 | B4: =VLOOKUP(A4,'FIP Conditions'!$A:$A,1,FALSE) -> SR117_00|CON_Q2_Q4 | C4: =A4=B4 -> TRUE
A5: AS004_17|CON_Q3_Q4 | B5: =VLOOKUP(A5,'FIP Conditions'!$A:$A,1,FALSE) -> AS004_17|CON_Q3_Q4 | C5: =A5=B5 -> TRUE
A6: AS133_00|CON_Q4 | B6: =VLOOKUP(A6,'FIP Conditions'!$A:$A,1,FALSE) -> AS133_00|CON_Q4 | C6: =A6=B6 -> TRUE
A7: AS137_00|CON_Q4 | B7: =VLOOKUP(A7,'FIP Conditions'!$A:$A,1,FALSE) -> AS137_00|CON_Q4 | C7: =A7=B7 -> TRUE
A8: AS139_00|CON_Q4 | B8: =VLOOKUP(A8,'FIP Conditions'!$A:$A,1,FALSE) -> AS139_00|CON_Q4 | C8: =A8=B8 -> TRUE
A9: AS142_00|CON_Q4 | B9: =VLOOKUP(A9,'FIP Conditions'!$A:$A,1,FALSE) -> AS142_00|CON_Q4 | C9: =A9=B9 -> TRUE
A10: AS168_00|CON_Q4 | B10: =VLOOKUP(A10,'FIP Conditions'!$A:$A,1,FALSE) -> AS168_00|CON_Q4 | C10: =A10=B10 -> TRUE
A11: LS013_17|CON_Q3_Q4 | B11: =VLOOKUP(A11,'FIP Conditions'!$A:$A,1,FALSE) -> LS013_17|CON_Q3_Q4 | C11: =A11=B11 -> TRUE
A12: LS142_00|CON_Q4 | B12: =VLOOKUP(A12,'FIP Conditions'!$A:$A,1,FALSE) -> LS142_00|CON_Q4 | C12: =A12=B12 -> TRUE
A13: S281_00|CON_Q4 | B13: =VLOOKUP(A13,'FIP Conditions'!$A:$A,1,FALSE) -> S281_00|CON_Q4 | C13: =A13=B13 -> TRUE
... A19: S463_00|CON_Q4 | B19: =VLOOKUP(A19,'FIP Conditions'!$A:$A,1,FALSE) -> S463_00|CON_Q4 | C19: =A19=B19 -> TRUE
